<mujoco model="template">
  <!-- This model has been converted from an OpenSim model. Model conversion by MyoConverter https://github.com/MyoHub/myoconverter. This model is licensed under Apache 2.0. -->
  <!-- Credits from the original OpenSim model. Note! If the following has any license information, it applies to the original OpenSim model. Credits: Arnold, E.M., Hamner, S.R., Ward, S.R., Lieber, R. L., and Delp, S.L.
			Modified by Adan Dominguez for a simplified version to be added into myosuite -->
  <!-- Note: inertiagrouprange="0 1" means that groups 0-1 will be used to infer masses/inertias, and groups 2-5 are
  only for visualisation (e.g. wrapping objects) !-->
  <compiler inertiafromgeom="auto" angle="radian" balanceinertia="true" boundmass="0.001" boundinertia="0.001" inertiagrouprange="0 1">
    <lengthrange inttotal="50" useexisting="true"/>
  </compiler>
  <option collision="predefined"/>
  <visual>
    <scale framelength="0.5" framewidth="0.01"/>
  </visual>
  <default>
    <joint limited="true" damping="0.05" armature="0.00001" stiffness="0"/>
    <geom rgba="0.8 0.6 .4 1" margin="0.001"/>
    <site size="0.001"/>
    <tendon width="0.005" rgba=".95 .3 .3 1" limited="false"/>
    <default class="muscle">
      <muscle ctrllimited="true" ctrlrange="0 1" scale="200"/>
    </default>
    <default class="motor">
      <general gainprm="5 0 0 0 0 0 0 0 0 0"/>
    </default>
  </default>
  <option timestep="0.002"/>
  <!-- nuser_jnt=1, the parameter is used to store default value of the joint, and nkey=1 to store keyframe with
   default joint positions set !-->
  <size njmax="1000" nconmax="400" nuser_jnt="1" nkey="1"/>
  <worldbody>
    <!-- The converter script assumes a body named 'ground' exists as a child element of worldbody -->
    <body name="ground" euler="1.571 0 0">
      <geom name="ground-plane" pos="0 0 0" euler="-1.571 0 0" size="10 10 0.125" type="plane" rgba="1.0 0.7 0.4 1.0" condim="3"/>
    </body>
    <light directional="true"/>
    <body name="pelvis" pos="0 0 0" euler="1.571 0 0">
      <inertial mass="11.776999999999999" pos="-0.070699999999999999 0 0" fullinertia="0.1028 0.087099999999999997 0.0579 0 0 0"/>
      <geom name="pelvis_geom_1" type="mesh" mesh="pelvis_geom_1_r_pelvis" rgba="1 1 1 1" group="0"/>
      <geom name="pelvis_geom_2" type="mesh" mesh="pelvis_geom_2_l_pelvis" rgba="1 1 1 1" group="0"/>
      <geom name="pelvis_geom_3" type="mesh" mesh="pelvis_geom_3_sacrum" rgba="1 1 1 1" group="0"/>
      <geom name="Gmax1_at_pelvis_r_cylinder" type="cylinder" euler="-0.6 0.45 0" pos="-0.077 -0.099 0.061" size="0.04 0.075" rgba="0.19 0.83 0.78 0.2" group="2"/>
      <site name="Gmax1_at_pelvis_r_sidesite" pos="-0.1139 -0.08893 0.07572" size="0.0005"/>
      <geom name="Gmax2_at_pelvis_r_cylinder" type="cylinder" euler="-0.75 0.39 0" pos="-0.08 -0.083 0.068" size="0.04 0.05" rgba="0.19 0.83 0.78 0.2" group="2"/>
      <geom name="Gmax3_at_pelvis_r_cylinder" type="cylinder" euler="-0.1 0 0" pos="-0.083 -0.088 0.068" size="0.04 0.05" rgba="0.19 0.83 0.78 0.2" group="2"/>
      <geom name="Gmax1_at_pelvis_l_cylinder" type="cylinder" euler="0.6 -0.45 0" pos="-0.077 -0.099 -0.061" size="0.04 0.075" rgba="0.19 0.83 0.78 0.2" group="2"/>
      <site name="Gmax1_at_pelvis_l_sidesite" pos="-0.1139 -0.08893 -0.07572" size="0.0005"/>
      <geom name="Gmax2_at_pelvis_l_cylinder" type="cylinder" euler="0.75 -0.39 0" pos="-0.08 -0.083 -0.068" size="0.04 0.05" rgba="0.19 0.83 0.78 0.2" group="2"/>
      <geom name="Gmax3_at_pelvis_l_cylinder" type="cylinder" euler="0.1 0 0" pos="-0.083 -0.088 -0.068" size="0.04 0.05" rgba="0.19 0.83 0.78 0.2" group="2"/>
      <geom name="PS_at_brim_r_cylinder" type="cylinder" euler="-0.25 -0.27 0.1" pos="-0.074 -0.06 0.0656" size="0.05 0.05" rgba="0.19 0.83 0.78 0.2" group="2"/>
      <site name="PS_at_brim_r_sidesite" pos="-0.06909 -0.1088 0.07947" size="0.0005"/>
      <geom name="PS_at_brim_l_cylinder" type="cylinder" euler="0.25 0.27 0.1" pos="-0.074 -0.06 -0.0656" size="0.05 0.05" rgba="0.19 0.83 0.78 0.2" group="2"/>
      <site name="PS_at_brim_l_sidesite" pos="-0.06909 -0.1088 -0.07947" size="0.0005"/>
      <geom name="IL_at_brim_r_cylinder" type="cylinder" euler="-0.32 -0.24 0.9" pos="-0.071 -0.065 0.0756" size="0.0549 0.05" rgba="0.19 0.83 0.78 0.2" group="2"/>
      <site name="IL_at_brim_r_sidesite" pos="-0.02847 -0.09471 0.09641" size="0.0005"/>
      <geom name="IL_at_brim_l_cylinder" type="cylinder" euler="0.32 0.24 0.9" pos="-0.071 -0.065 -0.0756" size="0.0549 0.05" rgba="0.19 0.83 0.78 0.2" group="2"/>
      <site name="IL_at_brim_l_sidesite" pos="-0.02847 -0.09471 -0.09641" size="0.0005"/>
      <joint name="pelvis_tx" range="-5 5" limited="true" user="0.0" ref="0" axis="1 0 0" type="slide" damping="0" stiffness="0"/>
      <joint name="pelvis_ty" range="-1 2" limited="true" user="0.93" ref="0" axis="0 1 0" type="slide" damping="0" stiffness="0"/>
      <joint name="pelvis_tz" range="-3 3" limited="true" user="0.0" ref="0" axis="0 0 1" type="slide" damping="0" stiffness="0"/>
      <joint name="pelvis_tilt" range="-1.571 1.571" limited="true" user="0.0" ref="0" axis="0 0 1" type="hinge" damping="0" stiffness="0"/>
      <joint name="pelvis_list" range="-1.571 1.571" limited="true" user="0.0" ref="0" axis="1 0 0" type="hinge" damping="0" stiffness="0"/>
      <joint name="pelvis_rotation" range="-1.571 1.571" limited="true" user="0.0" ref="0" axis="0 1 0" type="hinge" damping="0" stiffness="0"/>
      <body name="femur_r" pos="-0.05628 -0.07849 0.07726" euler="-0 0 0">
        <inertial mass="9.3013999999999992" pos="0 -0.17000000000000001 0" fullinertia="0.13389999999999999 0.035099999999999999 0.14119999999999999 0 0 0"/>
        <geom name="femur_r_geom_1" type="mesh" mesh="femur_r_geom_1_femur_r" rgba="1 1 1 1" group="0"/>
        <geom name="Gastroc_at_condyles_r_cylinder" type="cylinder" euler="0 0 0" pos="0.005 -0.41 0" size="0.025 0.05" rgba="0.19 0.83 0.78 0.2" group="2"/>
        <geom name="KnExt_at_fem_r_cylinder" type="cylinder" euler="-0.06234 0.05076 0" pos="0.003588 -0.4027 0.002091" size="0.025 0.05" rgba="0.19 0.83 0.78 0.2" group="2"/>
        <geom name="AB_at_femshaft_r_cylinder" type="cylinder" euler="1.662 0.1866 0" pos="0.01464 -0.1126 0.02337" size="0.0165 0.035" rgba="0.19 0.83 0.78 0.2" group="2"/>
        <geom name="AL_at_femshaft_r_cylinder" type="cylinder" euler="1.777 0.1365 0" pos="0.03073 -0.2319 0.01511" size="0.0201 0.05" rgba="0.19 0.83 0.78 0.2" group="2"/>
        <geom name="AMprox_at_femshaft_r_cylinder" type="cylinder" euler="1.611 0.1866 0" pos="0.005183 -0.07289 0.0254" size="0.0211 0.035" rgba="0.19 0.83 0.78 0.2" group="2"/>
        <geom name="AMmid_at_femshaft_r_cylinder" type="cylinder" euler="1.611 0.1366 0" pos="0.02301 -0.1607 0.02058" size="0.0214 0.06" rgba="0.19 0.83 0.78 0.2" group="2"/>
        <geom name="AMdist_at_femshaft_r_cylinder" type="cylinder" euler="1.712 0.1866 0" pos="0.03161 -0.2607 0.009365" size="0.0218 0.1" rgba="0.19 0.83 0.78 0.2" group="2"/>
        <geom name="AMisch_at_condyles_r_cylinder" type="cylinder" euler="1.711 -0.4634 0" pos="-0.02265 -0.3768 -0.003154" size="0.04 0.12" rgba="0.19 0.83 0.78 0.2" group="2"/>
        <geom name="PECT_at_femshaft_r_cylinder" type="cylinder" euler="1.813 0.2763 0" pos="0.006086 -0.0845 0.03044" size="0.015 0.025" rgba="0.19 0.83 0.78 0.2" group="2"/>
        <joint name="hip_flexion_r" range="-0.5236 2.094" limited="true" user="0.0" ref="0" axis="0 0 1" type="hinge"/>
        <joint name="hip_adduction_r" range="-0.8727 0.5236" limited="true" user="0.0" ref="0" axis="1 0 0" type="hinge"/>
        <joint name="hip_rotation_r" range="-0.6981 0.6981" limited="true" user="0.0" ref="0" axis="0 1 0" type="hinge"/>
        <body name="tibia_r" pos="-4.6e-07 -0.4044 -0.001265" euler="-0 0 0">
          <inertial mass="3.7075" pos="0 -0.1867 0" fullinertia="0.0504 0.0051000000000000004 0.0511 0 0 0"/>
          <geom name="tibia_r_geom_1" type="mesh" mesh="tibia_r_geom_1_tibia_r" rgba="1 1 1 1" group="0"/>
          <geom name="tibia_r_geom_2" type="mesh" mesh="tibia_r_geom_2_r_fibula" rgba="1 1 1 1" group="0"/>
          <geom name="GasLat_at_shank_r_cylinder" type="cylinder" euler="2.967 -0.2797 -1.478" pos="-0.0074 -0.074 -0.0033" size="0.055 0.05" rgba="0.19 0.83 0.78 0.2" group="2"/>
          <site name="GasLat_at_shank_r_sidesite" pos="-0.06099 -0.06623 0.01096" size="0.0005"/>
          <geom name="GasMed_at_shank_r_cylinder" type="cylinder" euler="2.967 0.02797 -1.478" pos="-0.0074 -0.074 -0.0033" size="0.055 0.05" rgba="0.19 0.83 0.78 0.2" group="2"/>
          <site name="GasMed_at_shank_r_sidesite" pos="-0.06314 -0.06917 -0.005735" size="0.0005"/>
          <geom name="GR_at_condyles_r_cylinder" type="cylinder" euler="0 -0.4 0" pos="-0.003 -0.02 0" size="0.036 0.05" rgba="0.19 0.83 0.78 0.2" group="2"/>
          <geom name="SM_at_condyles_r_cylinder" type="cylinder" euler="0 -0.1 0" pos="-0.001 -0.02 0" size="0.0352 0.05" rgba="0.19 0.83 0.78 0.2" group="2"/>
          <geom name="ST_at_condyles_r_cylinder" type="cylinder" euler="0 -0.2 0" pos="-0.002 -0.0205 0" size="0.0425 0.05" rgba="0.19 0.83 0.78 0.2" group="2"/>
          <geom name="BF_at_gastroc_r_cylinder" type="cylinder" euler="0 0 0" pos="-0.058 -0.06 0" size="0.03 0.075" rgba="0.19 0.83 0.78 0.2" group="2"/>
          <site name="BF_at_gastroc_r_sidesite" pos="-0.058 -0.029 0" size="0.0005"/>
          <joint name="walker_knee_r_translation1" range="0 0.001599" limited="true" user="9.537334105542278e-08" ref="0" axis="-0.1243 0.9898 -0.07016" type="slide"/>
          <joint name="walker_knee_r_translation2" range="0 0.006792" limited="true" user="7.69254287005805e-11" ref="0" axis="0.9922 0.124 -0.008789" type="slide"/>
          <joint name="knee_angle_r" range="0 2.094" limited="true" user="0.0" ref="0" axis="-4.566e-07 -0.07071 -0.9975" type="hinge"/>
          <joint name="walker_knee_r_rotation2" range="-0.001678 0.03354" limited="true" user="-1.4732523270777342e-08" ref="0" axis="0.9922 0.124 -0.008789" type="hinge"/>
          <joint name="walker_knee_r_rotation3" range="0 0.2628" limited="true" user="1.0893911744913609e-08" ref="0" axis="-0.1243 0.9898 -0.07016" type="hinge"/>
          <body name="talus_r" pos="-0.01 -0.4 0" euler="-0 0 -1.735e-18">
            <inertial mass="0.10000000000000001" pos="0 0 0" fullinertia="0.001 0.001 0.001 0 0 0"/>
            <geom name="talus_r_geom_1" type="mesh" mesh="talus_r_geom_1_r_talus" rgba="1 1 1 0" group="0"/>
            <joint name="ankle_angle_r" range="-0.6981 0.5236" limited="true" user="0.0" ref="0" type="hinge" axis="-0.105 -0.174 0.9791"/>
            <body name="calcn_r" pos="-0.04877 -0.04195 0.00792" euler="-0 0 0">
              <inertial mass="1.25" pos="0.10000000000000001 0.029999999999999999 0" fullinertia="0.0014 0.0038999999999999998 0.0041000000000000003 0 0 0"/>
              <geom name="calcn_r_geom_1" type="mesh" mesh="calcn_r_geom_1_r_foot" rgba="1 1 1 1" group="0"/>
              <joint name="subtalar_angle_r" range="-0.3491 0.3491" limited="true" user="0.0" ref="0" type="hinge" axis="0.7872 0.6047 -0.1209"/>
              <body name="toes_r" pos="0.1788 -0.002 0.00108" euler="-0 0 0">
                <inertial mass="0.21659999999999999" pos="0.034599999999999999 0.0060000000000000001 -0.017500000000000002" fullinertia="0.0001 0.00020000000000000001 0.001 0 0 0"/>
                <geom name="toes_r_geom_1" type="mesh" mesh="toes_r_geom_1_r_bofoot" rgba="1 1 1 1" group="0"/>
                <joint name="mtp_angle_r" range="-0.5236 0.5236" limited="true" user="0.0" ref="0" type="hinge" axis="0.581 2.16e-06 -0.8139"/>
                <site name="edl_r_edl_r-P5" pos="0.00029999999999999997 0.0047000000000000002 0.015299999999999999"/>
                <site name="edl_r_edl_r-P6" pos="0.044299999999999999 -0.00040000000000000002 0.025000000000000001"/>
                <site name="ehl_r_ehl_r-P7" pos="0.0298 0.0041000000000000003 -0.024500000000000001"/>
                <site name="ehl_r_ehl_r-P8" pos="0.056300000000000003 0.0033999999999999998 -0.018599999999999998"/>
                <site name="fdl_r_fdl_r-P6" pos="-0.0019 -0.0077999999999999996 0.0147"/>
                <site name="fdl_r_fdl_r-P7" pos="0.028500000000000001 -0.0071000000000000004 0.021499999999999998"/>
                <site name="fdl_r_fdl_r-P8" pos="0.0441 -0.0060000000000000001 0.024199999999999999"/>
                <site name="fhl_r_fhl_r-P6" pos="0.0155 -0.0064000000000000003 -0.026499999999999999"/>
                <site name="fhl_r_fhl_r-P7" pos="0.0562 -0.010200000000000001 -0.018100000000000002"/>
              </body>
              <site name="edl_r_edl_r-P3" pos="0.091899999999999996 0.035999999999999997 0.00080000000000000004"/>
              <site name="edl_r_edl_r-P4" pos="0.16159999999999999 0.0054999999999999997 0.012999999999999999"/>
              <site name="ehl_r_ehl_r-P4" pos="0.097000000000000003 0.038899999999999997 -0.021100000000000001"/>
              <site name="ehl_r_ehl_r-P5" pos="0.1293 0.0309 -0.025700000000000001"/>
              <site name="ehl_r_ehl_r-P6" pos="0.1734 0.013899999999999999 -0.028000000000000001"/>
              <site name="fdl_r_fdl_r-P3" pos="0.0436 0.0315 -0.028000000000000001"/>
              <site name="fdl_r_fdl_r-P4" pos="0.070800000000000002 0.017600000000000001 -0.0263"/>
              <site name="fdl_r_fdl_r-P5" pos="0.1658 -0.0080999999999999996 0.011599999999999999"/>
              <site name="fhl_r_fhl_r-P3" pos="0.037400000000000003 0.0276 -0.0241"/>
              <site name="fhl_r_fhl_r-P4" pos="0.1038 0.0067999999999999996 -0.025600000000000001"/>
              <site name="fhl_r_fhl_r-P5" pos="0.1726 -0.0053 -0.0269"/>
              <site name="gaslat_r_gaslat_r-P2" pos="0.0044000000000000003 0.031 -0.0053"/>
              <site name="gasmed_r_gasmed_r-P2" pos="0.0044000000000000003 0.031 -0.0053"/>
              <site name="perbrev_r_perbrev_r-P4" pos="0.047100000000000003 0.027 0.023300000000000001"/>
              <site name="perbrev_r_perbrev_r-P5" pos="0.067699999999999996 0.021899999999999999 0.034299999999999997"/>
              <site name="perlong_r_perlong_r-P4" pos="0.043799999999999999 0.023 0.022100000000000002"/>
              <site name="perlong_r_perlong_r-P5" pos="0.068099999999999994 0.0106 0.028400000000000002"/>
              <site name="perlong_r_perlong_r-P6" pos="0.085199999999999998 0.0068999999999999999 0.0118"/>
              <site name="perlong_r_perlong_r-P7" pos="0.1203 0.0085000000000000006 -0.0184"/>
              <site name="soleus_r_soleus_r-P2" pos="0.0044000000000000003 0.031 -0.0053"/>
              <site name="tibant_r_tibant_r-P4" pos="0.1166 0.0178 -0.030499999999999999"/>
              <site name="tibpost_r_tibpost_r-P3" pos="0.041700000000000001 0.033399999999999999 -0.0286"/>
              <site name="tibpost_r_tibpost_r-P4" pos="0.077200000000000005 0.015900000000000001 -0.0281"/>
            </body>
          </body>
          <site name="bflh_r_bflh_r-P2" pos="-0.033700000000000001 -0.035000000000000003 0.0253"/>
          <site name="bflh_r_bflh_r-P3" pos="-0.0287 -0.045499999999999999 0.030300000000000001"/>
          <site name="bfsh_r_bfsh_r-P2" pos="-0.030099999999999998 -0.0419 0.031800000000000002"/>
          <site name="edl_r_edl_r-P1" pos="-0.016 -0.1157 0.020500000000000001"/>
          <site name="edl_r_edl_r-P2" pos="0.016400000000000001 -0.376 0.0112"/>
          <site name="ehl_r_ehl_r-P1" pos="-0.014 -0.155 0.0189"/>
          <site name="ehl_r_ehl_r-P2" pos="0.0071000000000000004 -0.29089999999999999 0.016400000000000001"/>
          <site name="ehl_r_ehl_r-P3" pos="0.02 -0.36930000000000002 -0.0028"/>
          <site name="fdl_r_fdl_r-P1" pos="-0.0023 -0.1832 -0.0018"/>
          <site name="fdl_r_fdl_r-P2" pos="-0.017600000000000001 -0.36449999999999999 -0.0124"/>
          <site name="fhl_r_fhl_r-P1" pos="-0.031 -0.21629999999999999 0.02"/>
          <site name="fhl_r_fhl_r-P2" pos="-0.024199999999999999 -0.36709999999999998 -0.0076"/>
          <site name="grac_r_grac_r-P2" pos="-0.018419999999999999 -0.047550000000000002 -0.029610000000000001"/>
          <site name="grac_r_grac_r-P3" pos="0.0017799999999999999 -0.069620000000000001 -0.015730000000000001"/>
          <site name="GR_at_condyles_r_cylinder_grac_r_1_sidesite" pos="-0.01538 -0.002981 -0.03203" size="0.0005"/>
          <site name="perbrev_r_perbrev_r-P1" pos="-0.024299999999999999 -0.25319999999999998 0.025100000000000001"/>
          <site name="perbrev_r_perbrev_r-P2" pos="-0.0339 -0.38929999999999998 0.024899999999999999"/>
          <site name="perbrev_r_perbrev_r-P3" pos="-0.028500000000000001 -0.40039999999999998 0.025499999999999998"/>
          <site name="perlong_r_perlong_r-P1" pos="-0.02 -0.13730000000000001 0.028199999999999999"/>
          <site name="perlong_r_perlong_r-P2" pos="-0.031699999999999999 -0.39000000000000001 0.023699999999999999"/>
          <site name="perlong_r_perlong_r-P3" pos="-0.027199999999999998 -0.40139999999999998 0.024"/>
          <site name="recfem_r_recfem_r-P5" pos="0.032599999999999997 -0.063119999999999996 -0.00046999999999999999"/>
          <site name="sart_r_sart_r-P3" pos="-0.025100000000000001 -0.040099999999999997 -0.036499999999999998"/>
          <site name="sart_r_sart_r-P4" pos="-0.015900000000000001 -0.059900000000000002 -0.0264"/>
          <site name="sart_r_sart_r-P5" pos="0.013599999999999999 -0.081000000000000003 -0.0025999999999999999"/>
          <site name="semimem_r_semimem_r-P2" pos="-0.029000000000000001 -0.041700000000000001 -0.019599999999999999"/>
          <site name="SM_at_condyles_r_cylinder_semimem_r_1_sidesite" pos="-0.029 -0.0417 -0.0196" size="0.0005"/>
          <site name="semiten_r_semiten_r-P2" pos="-0.031199999999999999 -0.050799999999999998 -0.0229"/>
          <site name="semiten_r_semiten_r-P3" pos="0.0019 -0.077299999999999994 -0.0117"/>
          <site name="ST_at_condyles_r_cylinder_semiten_r_1_sidesite" pos="-0.03451 -0.004694 -0.02419" size="0.0005"/>
          <site name="soleus_r_soleus_r-P1" pos="-0.0076 -0.091600000000000001 0.0097999999999999997"/>
          <site name="tfl_r_tfl_r-P4" pos="0.010800000000000001 -0.041000000000000002 0.034599999999999999"/>
          <site name="tibant_r_tibant_r-P1" pos="0.0154 -0.13120000000000001 0.016199999999999999"/>
          <site name="tibant_r_tibant_r-P2" pos="0.025100000000000001 -0.19059999999999999 0.012800000000000001"/>
          <site name="tibant_r_tibant_r-P3" pos="0.023300000000000001 -0.3659 -0.0132"/>
          <site name="tibpost_r_tibpost_r-P1" pos="-0.0041000000000000003 -0.13039999999999999 0.0103"/>
          <site name="tibpost_r_tibpost_r-P2" pos="-0.016400000000000001 -0.36549999999999999 -0.017500000000000002"/>
          <site name="vasint_r_vasint_r-P5" pos="0.032570000000000002 -0.063200000000000006 0.00042999999999999999"/>
          <site name="vaslat_r_vaslat_r-P5" pos="0.032539999999999999 -0.063380000000000006 0.00511"/>
          <site name="vasmed_r_vasmed_r-P5" pos="0.031899999999999998 -0.063570000000000002 -0.0067799999999999996"/>
        </body>
        <body name="patella_r" pos="-0.00809 -0.408 -0.00275" euler="-0 0 0">
          <inertial mass="0.086199999999999999" pos="0.0018 0.0264 0" fullinertia="2.8700000000000001e-06 1.311e-05 1.311e-05 0 0 0"/>
          <geom name="patella_r_geom_1" type="mesh" mesh="patella_r_geom_1_r_patella" rgba="1 1 1 1" group="0"/>
          <joint name="patellofemoral_r_translation1" range="-0.0227 0.0524" limited="true" user="0.052419230882789325" ref="0" axis="1 0 0" type="slide"/>
          <joint name="patellofemoral_r_translation2" range="-0.0408 -0.0108" limited="true" user="-0.010828128987922722" ref="0" axis="0 1 0" type="slide"/>
          <joint name="patellofemoral_r_translation3" limited="false" ref="0" axis="0 0 1" type="slide"/>
          <joint name="patellofemoral_r_rotation1" range="-1.786 0.001137" limited="true" user="0.010505984997235651" ref="0" axis="0 0 1" type="hinge"/>
          <site name="recfem_r_recfem_r-P2" pos="0.01 0.049000000000000002 0.00069999999999999999"/>
          <site name="recfem_r_recfem_r-P3" pos="0.0121 0.043700000000000003 -0.001"/>
          <site name="recfem_r_recfem_r-P4" pos="0.0050000000000000001 0.00247 3.0000000000000001e-05"/>
          <site name="vasint_r_vasint_r-P3" pos="0.0057999999999999996 0.048000000000000001 -0.00059999999999999995"/>
          <site name="vasint_r_vasint_r-P4" pos="0.0050000000000000001 0.00247 -0.00038999999999999999"/>
          <site name="vaslat_r_vaslat_r-P3" pos="0.0103 0.042299999999999997 0.0141"/>
          <site name="vaslat_r_vaslat_r-P4" pos="0.0050000000000000001 0.00247 0.0073299999999999997"/>
          <site name="vasmed_r_vasmed_r-P3" pos="0.0063 0.044499999999999998 -0.017000000000000001"/>
          <site name="vasmed_r_vasmed_r-P4" pos="0.0050000000000000001 0.00247 -0.0085000000000000006"/>
        </body>
        <site name="addbrev_r_addbrev_r-P2" pos="-0.002 -0.11799999999999999 0.024899999999999999"/>
        <site name="AB_at_femshaft_r_cylinder_addbrev_r_1_sidesite" pos="0.001111 -0.106 0.01444" size="0.0005"/>
        <site name="addlong_r_addlong_r-P2" pos="0.011259999999999999 -0.23937 0.01583"/>
        <site name="AL_at_femshaft_r_cylinder_addlong_r_1_sidesite" pos="0.01126 -0.2394 0.01583" size="0.0005"/>
        <site name="addmagDist_r_addmagDist_r-P2" pos="0.01125 -0.26250000000000001 0.019300000000000001"/>
        <site name="AMdist_at_femshaft_r_cylinder_addmagDist_r_1_sidesite" pos="0.01125 -0.2625 0.0193" size="0.0005"/>
        <site name="addmagIsch_r_addmagIsch_r-P2" pos="0.00481 -0.38796999999999998 -0.032730000000000002"/>
        <site name="AMisch_at_condyles_r_cylinder_addmagIsch_r_1_sidesite" pos="0.00481 -0.388 -0.03273" size="0.0005"/>
        <site name="addmagMid_r_addmagMid_r-P2" pos="0.0024199999999999998 -0.16239999999999999 0.029219999999999999"/>
        <site name="AMmid_at_femshaft_r_cylinder_addmagMid_r_1_sidesite" pos="0.00242 -0.1624 0.02922" size="0.0005"/>
        <site name="addmagProx_r_addmagProx_r-P2" pos="-0.015270000000000001 -0.07886 0.03202"/>
        <site name="AMprox_at_femshaft_r_cylinder_addmagProx_r_1_sidesite" pos="-0.01624 -0.07348 0.02002" size="0.0005"/>
        <site name="bfsh_r_bfsh_r-P1" pos="0.0050000000000000001 -0.21110000000000001 0.023400000000000001"/>
        <site name="gaslat_r_gaslat_r-P1" pos="-0.0030000000000000001 -0.38140000000000002 0.027699999999999999"/>
        <site name="Gastroc_at_condyles_r_cylinder_gaslat_r_1_sidesite" pos="-0.008708 -0.4296 0.02477" size="0.0005"/>
        <site name="gasmed_r_gasmed_r-P1" pos="0.0080000000000000002 -0.37880000000000003 -0.020799999999999999"/>
        <site name="Gastroc_at_condyles_r_cylinder_gasmed_r_1_sidesite" pos="0.00107 -0.4273 -0.01834" size="0.0005"/>
        <site name="glmax1_r_glmax1_r-P3" pos="-0.044400000000000002 -0.032599999999999997 0.030200000000000001"/>
        <site name="glmax1_r_glmax1_r-P4" pos="-0.027699999999999999 -0.056599999999999998 0.047"/>
        <site name="glmax2_r_glmax2_r-P3" pos="-0.044999999999999998 -0.058400000000000001 0.0252"/>
        <site name="glmax2_r_glmax2_r-P4" pos="-0.015599999999999999 -0.1016 0.0419"/>
        <site name="glmax3_r_glmax3_r-P3" pos="-0.0281 -0.1125 0.0094000000000000004"/>
        <site name="glmax3_r_glmax3_r-P4" pos="-0.0060000000000000001 -0.1419 0.041099999999999998"/>
        <site name="glmed1_r_glmed1_r-P2" pos="-0.0218 -0.0117 0.055500000000000001"/>
        <site name="glmed2_r_glmed2_r-P2" pos="-0.0258 -0.0057999999999999996 0.052699999999999997"/>
        <site name="glmed3_r_glmed3_r-P2" pos="-0.0309 -0.0047000000000000002 0.051799999999999999"/>
        <site name="glmin1_r_glmin1_r-P2" pos="-0.0071999999999999998 -0.0104 0.056000000000000001"/>
        <site name="glmin2_r_glmin2_r-P2" pos="-0.0095999999999999992 -0.0104 0.056000000000000001"/>
        <site name="glmin3_r_glmin3_r-P2" pos="-0.0135 -0.0083000000000000001 0.055"/>
        <site name="iliacus_r_iliacus_r-P3" pos="-0.0023 -0.056500000000000002 0.013899999999999999"/>
        <site name="iliacus_r_iliacus_r-P4" pos="-0.012200000000000001 -0.063700000000000007 0.019599999999999999"/>
        <site name="piri_r_piri_r-P3" pos="-0.014800000000000001 -0.0035999999999999999 0.043700000000000003"/>
        <site name="psoas_r_psoas_r-P3" pos="-0.0132 -0.046699999999999998 0.0045999999999999999"/>
        <site name="psoas_r_psoas_r-P4" pos="-0.0235 -0.052400000000000002 0.0088000000000000005"/>
        <site name="KnExt_at_fem_r_cylinder_recfem_r_3_sidesite" pos="-0.01586 -0.3969 -0.01417" size="0.0005"/>
        <site name="sart_r_sart_r-P2" pos="-0.0030000000000000001 -0.35680000000000001 -0.042099999999999999"/>
        <site name="tfl_r_tfl_r-P2" pos="0.029399999999999999 -0.099500000000000005 0.059700000000000003"/>
        <site name="tfl_r_tfl_r-P3" pos="0.010699999999999999 -0.40500000000000003 0.032399999999999998"/>
        <site name="vasint_r_vasint_r-P1" pos="0.029000000000000001 -0.19239999999999999 0.031"/>
        <site name="vasint_r_vasint_r-P2" pos="0.033500000000000002 -0.2084 0.028500000000000001"/>
        <site name="KnExt_at_fem_r_cylinder_vasint_r_3_sidesite" pos="-0.01606 -0.3961 -0.01358" size="0.0005"/>
        <site name="vaslat_r_vaslat_r-P1" pos="0.0047999999999999996 -0.18540000000000001 0.0349"/>
        <site name="vaslat_r_vaslat_r-P2" pos="0.0269 -0.2591 0.040899999999999999"/>
        <site name="KnExt_at_fem_r_cylinder_vaslat_r_3_sidesite" pos="-0.01877 -0.3968 0.01399" size="0.0005"/>
        <site name="vasmed_r_vasmed_r-P1" pos="0.014 -0.2099 0.018800000000000001"/>
        <site name="vasmed_r_vasmed_r-P2" pos="0.0356 -0.27689999999999998 0.00089999999999999998"/>
        <site name="KnExt_at_fem_r_cylinder_vasmed_r_4_sidesite" pos="-0.007846 -0.4075 -0.02075" size="0.0005"/>
        <site name="KnExt_at_fem_r_cylinder_vasmed_r_3_sidesite" pos="-0.007846 -0.4075 -0.02075" size="0.0005"/>
      </body>
      <body name="femur_l" pos="-0.05628 -0.07849 -0.07726" euler="-0 0 0">
        <inertial mass="9.3013999999999992" pos="0 -0.17000000000000001 0" fullinertia="0.13389999999999999 0.035099999999999999 0.14119999999999999 0 0 0"/>
        <geom name="femur_l_geom_1" type="mesh" mesh="femur_l_geom_1_femur_l" rgba="1 1 1 1" group="0"/>
        <geom name="Gastroc_at_condyles_l_cylinder" type="cylinder" euler="0 0 0" pos="0.005 -0.41 0" size="0.025 0.05" rgba="0.19 0.83 0.78 0.2" group="2"/>
        <geom name="KnExt_at_fem_l_cylinder" type="cylinder" euler="0.06234 -0.05076 0" pos="0.003588 -0.4027 -0.002091" size="0.025 0.05" rgba="0.19 0.83 0.78 0.2" group="2"/>
        <geom name="AB_at_femshaft_l_cylinder" type="cylinder" euler="-1.662 -0.1866 0" pos="0.01464 -0.1126 -0.02337" size="0.0165 0.035" rgba="0.19 0.83 0.78 0.2" group="2"/>
        <geom name="AL_at_femshaft_l_cylinder" type="cylinder" euler="-1.777 -0.1365 0" pos="0.03073 -0.2319 -0.01511" size="0.0201 0.05" rgba="0.19 0.83 0.78 0.2" group="2"/>
        <geom name="AMprox_at_femshaft_l_cylinder" type="cylinder" euler="-1.611 -0.1866 0" pos="0.005183 -0.07289 -0.0254" size="0.0211 0.035" rgba="0.19 0.83 0.78 0.2" group="2"/>
        <geom name="AMmid_at_femshaft_l_cylinder" type="cylinder" euler="-1.611 -0.1366 0" pos="0.02301 -0.1607 -0.02058" size="0.0214 0.06" rgba="0.19 0.83 0.78 0.2" group="2"/>
        <geom name="AMdist_at_femshaft_l_cylinder" type="cylinder" euler="-1.712 -0.1866 0" pos="0.03161 -0.2607 -0.009365" size="0.0218 0.1" rgba="0.19 0.83 0.78 0.2" group="2"/>
        <geom name="AMisch_at_condyles_l_cylinder" type="cylinder" euler="-1.711 0.4634 0" pos="-0.02265 -0.3768 0.003154" size="0.04 0.12" rgba="0.19 0.83 0.78 0.2" group="2"/>
        <geom name="PECT_at_femshaft_l_cylinder" type="cylinder" euler="-1.813 -0.2763 0" pos="0.006086 -0.0845 -0.03044" size="0.015 0.025" rgba="0.19 0.83 0.78 0.2" group="2"/>
        <joint name="hip_flexion_l" range="-0.5236 2.094" limited="true" user="0.0" ref="0" axis="0 0 1" type="hinge"/>
        <joint name="hip_adduction_l" range="-0.8727 0.5236" limited="true" user="-0.0" ref="0" axis="-1 -0 -0" type="hinge"/>
        <joint name="hip_rotation_l" range="-0.6981 0.6981" limited="true" user="-0.0" ref="0" axis="-0 -1 -0" type="hinge"/>
        <body name="tibia_l" pos="-4.6e-07 -0.4044 0.001265" euler="-0 0 0">
          <inertial mass="1.8537999999999999" pos="0 -0.10000000000000001 0" fullinertia="0.0063 0.0025500000000000002 0.0063874999999999999 0 0 0"/>
          <geom name="tibia_l_geom_1" type="mesh" mesh="tibia_l_geom_1_l_tib_cut" rgba="1 1 1 1" group="0"/>
          <geom name="tibia_l_geom_2" type="mesh" mesh="tibia_l_geom_2_l_fib_cut" rgba="1 1 1 1" group="0"/>
          <geom name="GasLat_at_shank_l_cylinder" type="cylinder" euler="-2.967 0.2797 -1.478" pos="-0.0074 -0.074 0.0033" size="0.055 0.05" rgba="0.19 0.83 0.78 0.2" group="2"/>
          <site name="GasLat_at_shank_l_sidesite" pos="-0.06099 -0.06623 -0.01096" size="0.0005"/>
          <geom name="GasMed_at_shank_l_cylinder" type="cylinder" euler="-2.967 -0.02797 -1.478" pos="-0.0074 -0.074 0.0033" size="0.055 0.05" rgba="0.19 0.83 0.78 0.2" group="2"/>
          <site name="GasMed_at_shank_l_sidesite" pos="-0.06314 -0.06917 0.005735" size="0.0005"/>
          <geom name="GR_at_condyles_l_cylinder" type="cylinder" euler="0 0.4 0" pos="-0.003 -0.02 0" size="0.036 0.05" rgba="0.19 0.83 0.78 0.2" group="2"/>
          <geom name="SM_at_condyles_l_cylinder" type="cylinder" euler="0 0.1 0" pos="-0.001 -0.02 0" size="0.0352 0.05" rgba="0.19 0.83 0.78 0.2" group="2"/>
          <geom name="ST_at_condyles_l_cylinder" type="cylinder" euler="0 0.2 0" pos="-0.002 -0.0205 0" size="0.0425 0.05" rgba="0.19 0.83 0.78 0.2" group="2"/>
          <geom name="BF_at_gastroc_l_cylinder" type="cylinder" euler="0 0 0" pos="-0.058 -0.06 0" size="0.03 0.075" rgba="0.19 0.83 0.78 0.2" group="2"/>
          <joint name="walker_knee_l_translation1" range="0 0.001599" limited="true" user="9.537334105542278e-08" ref="0" axis="-0.1243 0.9898 0.07016" type="slide"/>
          <joint name="walker_knee_l_translation2" range="-0.006792 0" limited="true" user="-7.69254287005805e-11" ref="0" axis="-0.9922 -0.124 -0.008789" type="slide"/>
          <joint name="knee_angle_l" range="0 2.094" limited="true" user="0.0" ref="0" axis="4.566e-07 0.07071 -0.9975" type="hinge"/>
          <joint name="walker_knee_l_rotation2" range="-0.001678 0.03354" limited="true" user="-1.4732523270777342e-08" ref="0" axis="-0.9922 -0.124 -0.008789" type="hinge"/>
          <joint name="walker_knee_l_rotation3" range="-0.2628 0" limited="true" user="-1.0893911744913609e-08" ref="0" axis="-0.1243 0.9898 0.07016" type="hinge"/>
          <body name="socket_l" pos="0 -0.2 0" euler="-0 0 0">
            <inertial mass="0.81086230000000004" pos="0 -0.095799999999999996 0" fullinertia="0.011499000000000001 0.00299 0.011665999999999999 0 0 0"/>
            <joint name="socket_piston_l" range="-0.03 0.03" limited="true" user="0.0" ref="0" axis="0 1 0" type="slide"/>
            <joint name="socket_rotation_l" range="-0.5236 0.5236" limited="true" user="0.0" ref="0" axis="0 1 -0.0001" type="hinge"/>
            <body name="pylon_l" pos="0 0 0" euler="-0 0 0">
              <inertial mass="0.180343" pos="0 -0.051200000000000002 0" fullinertia="0.001199 9.9900000000000002e-05 0.001199 0 0 0"/>
              <geom name="pylon_l_geom_1" type="mesh" mesh="pylon_l_geom_1_pylon" rgba="0.80000000000000004 0.80000000000000004 0.80000000000000004 1" group="0"/>
              <joint name="SP_rotation_l" range="-0.001 0.001" limited="true" user="0.0" ref="0" axis="0 1 -0.0001" type="hinge"/>
              <body name="foot_l" pos="-0.03705 -0.2 0.002567" euler="-0 0 0">
                <inertial mass="0.58330000000000004" pos="0.074700000000000003 -0.033500000000000002 0.002" fullinertia="0.0038 0.0035000000000000001 0.00056999999999999998 0 0 0"/>
                <joint name="ankle_angle_l" range="-0.6981 0.5236" limited="true" user="0.0" ref="0" axis="0 0 1" type="hinge"/>
                <joint name="ankle_evert_l" range="-0.8727 0.5236" limited="true" user="-0.0" ref="0" axis="-1 -0 -0" type="hinge"/>
                <joint name="ankle_ext_rot_l" range="-0.5236 0.5236" limited="true" user="0.174532478855694" ref="0" axis="-0 -1 -0" type="hinge"/>
              </body>
            </body>
          </body>
          <site name="bflh_l_bflh_l-P2" pos="-0.033700000000000001 -0.035000000000000003 -0.0253"/>
          <site name="bflh_l_bflh_l-P3" pos="-0.0287 -0.045499999999999999 -0.030300000000000001"/>
          <site name="bfsh_l_bfsh_l-P2" pos="-0.030099999999999998 -0.0419 -0.031800000000000002"/>
          <site name="grac_l_grac_l-P2" pos="-0.018419999999999999 -0.047550000000000002 0.029610000000000001"/>
          <site name="grac_l_grac_l-P3" pos="0.0017799999999999999 -0.069620000000000001 0.015730000000000001"/>
          <site name="GR_at_condyles_l_cylinder_grac_l_1_sidesite" pos="-0.01538 -0.002981 0.03203" size="0.0005"/>
          <site name="recfem_l_recfem_l-P5" pos="0.032599999999999997 -0.063119999999999996 0.00046999999999999999"/>
          <site name="sart_l_sart_l-P3" pos="-0.025100000000000001 -0.040099999999999997 0.036499999999999998"/>
          <site name="sart_l_sart_l-P4" pos="-0.015900000000000001 -0.059900000000000002 0.0264"/>
          <site name="sart_l_sart_l-P5" pos="0.013599999999999999 -0.081000000000000003 0.0025999999999999999"/>
          <site name="semimem_l_semimem_l-P2" pos="-0.029000000000000001 -0.041700000000000001 0.019599999999999999"/>
          <site name="SM_at_condyles_l_cylinder_semimem_l_1_sidesite" pos="-0.029 -0.0417 0.0196" size="0.0005"/>
          <site name="semiten_l_semiten_l-P2" pos="-0.031199999999999999 -0.050799999999999998 0.0229"/>
          <site name="semiten_l_semiten_l-P3" pos="0.0019 -0.077299999999999994 0.0117"/>
          <site name="ST_at_condyles_l_cylinder_semiten_l_1_sidesite" pos="-0.03451 -0.004694 0.02419" size="0.0005"/>
          <site name="tfl_l_tfl_l-P4" pos="0.010800000000000001 -0.041000000000000002 -0.034599999999999999"/>
          <site name="vasint_l_vasint_l-P5" pos="0.032570000000000002 -0.063200000000000006 -0.00042999999999999999"/>
          <site name="vaslat_l_vaslat_l-P5" pos="0.032539999999999999 -0.063380000000000006 -0.00511"/>
          <site name="vasmed_l_vasmed_l-P5" pos="0.031899999999999998 -0.063570000000000002 0.0067799999999999996"/>
        </body>
        <body name="patella_l" pos="-0.00809 -0.408 0.00275" euler="-0 0 0">
          <inertial mass="0.086199999999999999" pos="0.0018 0.0264 0" fullinertia="2.8700000000000001e-06 1.311e-05 1.311e-05 0 0 0"/>
          <geom name="patella_l_geom_1" type="mesh" mesh="patella_l_geom_1_l_pat" rgba="1 1 1 1" group="0"/>
          <joint name="patellofemoral_l_translation1" range="-0.0227 0.0524" limited="true" user="0.052419230882789325" ref="0" axis="1 0 0" type="slide"/>
          <joint name="patellofemoral_l_translation2" range="-0.0408 -0.0108" limited="true" user="-0.010828128987922722" ref="0" axis="0 1 0" type="slide"/>
          <joint name="patellofemoral_l_translation3" limited="false" ref="0" axis="0 0 1" type="slide"/>
          <joint name="patellofemoral_l_rotation1" range="-1.786 0.001137" limited="true" user="0.010505984997235651" ref="0" axis="0 0 1" type="hinge"/>
          <site name="recfem_l_recfem_l-P2" pos="0.01 0.049000000000000002 -0.00069999999999999999"/>
          <site name="recfem_l_recfem_l-P3" pos="0.0121 0.043700000000000003 0.001"/>
          <site name="recfem_l_recfem_l-P4" pos="0.0050000000000000001 0.00247 -3.0000000000000001e-05"/>
          <site name="vasint_l_vasint_l-P3" pos="0.0057999999999999996 0.048000000000000001 0.00059999999999999995"/>
          <site name="vasint_l_vasint_l-P4" pos="0.0050000000000000001 0.00247 0.00038999999999999999"/>
          <site name="vaslat_l_vaslat_l-P3" pos="0.0103 0.042299999999999997 -0.0141"/>
          <site name="vaslat_l_vaslat_l-P4" pos="0.0050000000000000001 0.00247 -0.0073299999999999997"/>
          <site name="vasmed_l_vasmed_l-P3" pos="0.0063 0.044499999999999998 0.017000000000000001"/>
          <site name="vasmed_l_vasmed_l-P4" pos="0.0050000000000000001 0.00247 0.0085000000000000006"/>
        </body>
        <site name="addbrev_l_addbrev_l-P2" pos="-0.002 -0.11799999999999999 -0.024899999999999999"/>
        <site name="AB_at_femshaft_l_cylinder_addbrev_l_1_sidesite" pos="0.001111 -0.106 -0.01444" size="0.0005"/>
        <site name="addlong_l_addlong_l-P2" pos="0.011259999999999999 -0.23937 -0.01583"/>
        <site name="AL_at_femshaft_l_cylinder_addlong_l_1_sidesite" pos="0.01126 -0.2394 -0.01583" size="0.0005"/>
        <site name="addmagDist_l_addmagDist_l-P2" pos="0.01125 -0.26250000000000001 -0.019300000000000001"/>
        <site name="AMdist_at_femshaft_l_cylinder_addmagDist_l_1_sidesite" pos="0.01125 -0.2625 -0.0193" size="0.0005"/>
        <site name="addmagIsch_l_addmagIsch_l-P2" pos="0.00481 -0.38796999999999998 0.032730000000000002"/>
        <site name="AMisch_at_condyles_l_cylinder_addmagIsch_l_1_sidesite" pos="0.00481 -0.388 0.03273" size="0.0005"/>
        <site name="addmagMid_l_addmagMid_l-P2" pos="0.0024199999999999998 -0.16239999999999999 -0.029219999999999999"/>
        <site name="AMmid_at_femshaft_l_cylinder_addmagMid_l_1_sidesite" pos="0.00242 -0.1624 -0.02922" size="0.0005"/>
        <site name="addmagProx_l_addmagProx_l-P2" pos="-0.015270000000000001 -0.07886 -0.03202"/>
        <site name="AMprox_at_femshaft_l_cylinder_addmagProx_l_1_sidesite" pos="-0.01624 -0.07348 -0.02002" size="0.0005"/>
        <site name="bfsh_l_bfsh_l-P1" pos="0.0050000000000000001 -0.21110000000000001 -0.023400000000000001"/>
        <site name="glmax1_l_glmax1_l-P3" pos="-0.044400000000000002 -0.032599999999999997 -0.030200000000000001"/>
        <site name="glmax1_l_glmax1_l-P4" pos="-0.027699999999999999 -0.056599999999999998 -0.047"/>
        <site name="glmax2_l_glmax2_l-P3" pos="-0.044999999999999998 -0.058400000000000001 -0.0252"/>
        <site name="glmax2_l_glmax2_l-P4" pos="-0.015599999999999999 -0.1016 -0.0419"/>
        <site name="glmax3_l_glmax3_l-P3" pos="-0.0281 -0.1125 -0.0094000000000000004"/>
        <site name="glmax3_l_glmax3_l-P4" pos="-0.0060000000000000001 -0.1419 -0.041099999999999998"/>
        <site name="glmed1_l_glmed1_l-P2" pos="-0.0218 -0.0117 -0.055500000000000001"/>
        <site name="glmed2_l_glmed2_l-P2" pos="-0.0258 -0.0057999999999999996 -0.052699999999999997"/>
        <site name="glmed3_l_glmed3_l-P2" pos="-0.0309 -0.0047000000000000002 -0.051799999999999999"/>
        <site name="glmin1_l_glmin1_l-P2" pos="-0.0071999999999999998 -0.0104 -0.056000000000000001"/>
        <site name="glmin2_l_glmin2_l-P2" pos="-0.0095999999999999992 -0.0104 -0.056000000000000001"/>
        <site name="glmin3_l_glmin3_l-P2" pos="-0.0135 -0.0083000000000000001 -0.055"/>
        <site name="iliacus_l_iliacus_l-P3" pos="-0.0023 -0.056500000000000002 -0.013899999999999999"/>
        <site name="iliacus_l_iliacus_l-P4" pos="-0.012200000000000001 -0.063700000000000007 -0.019599999999999999"/>
        <site name="piri_l_piri_l-P3" pos="-0.014800000000000001 -0.0035999999999999999 -0.043700000000000003"/>
        <site name="psoas_l_psoas_l-P3" pos="-0.0132 -0.046699999999999998 -0.0045999999999999999"/>
        <site name="psoas_l_psoas_l-P4" pos="-0.0235 -0.052400000000000002 -0.0088000000000000005"/>
        <site name="KnExt_at_fem_l_cylinder_recfem_l_3_sidesite" pos="-0.01586 -0.3969 0.01417" size="0.0005"/>
        <site name="sart_l_sart_l-P2" pos="-0.0030000000000000001 -0.35680000000000001 0.042099999999999999"/>
        <site name="tfl_l_tfl_l-P2" pos="0.029399999999999999 -0.099500000000000005 -0.059700000000000003"/>
        <site name="tfl_l_tfl_l-P3" pos="0.010699999999999999 -0.40500000000000003 -0.032399999999999998"/>
        <site name="vasint_l_vasint_l-P1" pos="0.029000000000000001 -0.19239999999999999 -0.031"/>
        <site name="vasint_l_vasint_l-P2" pos="0.033500000000000002 -0.2084 -0.028500000000000001"/>
        <site name="KnExt_at_fem_l_cylinder_vasint_l_3_sidesite" pos="-0.01606 -0.3961 0.01358" size="0.0005"/>
        <site name="vaslat_l_vaslat_l-P1" pos="0.0047999999999999996 -0.18540000000000001 -0.0349"/>
        <site name="vaslat_l_vaslat_l-P2" pos="0.0269 -0.2591 -0.040899999999999999"/>
        <site name="KnExt_at_fem_l_cylinder_vaslat_l_3_sidesite" pos="-0.01877 -0.3968 -0.01399" size="0.0005"/>
        <site name="vasmed_l_vasmed_l-P1" pos="0.014 -0.2099 -0.018800000000000001"/>
        <site name="vasmed_l_vasmed_l-P2" pos="0.0356 -0.27689999999999998 -0.00089999999999999998"/>
        <site name="KnExt_at_fem_l_cylinder_vasmed_l_4_sidesite" pos="-0.007846 -0.4075 0.02075" size="0.0005"/>
        <site name="KnExt_at_fem_l_cylinder_vasmed_l_3_sidesite" pos="-0.007846 -0.4075 0.02075" size="0.0005"/>
      </body>
      <body name="torso" pos="-0.1007 0.0815 0" euler="-0 0 0">
        <inertial mass="26.826599999999999" pos="-0.029999999999999999 0.32000000000000001 0" fullinertia="1.4744999999999999 0.75549999999999995 1.4314 0 0 0"/>
        <geom name="torso_geom_1" type="mesh" mesh="torso_geom_1_hat_spine" rgba="1 1 1 1" group="0"/>
        <geom name="torso_geom_2" type="mesh" mesh="torso_geom_2_hat_jaw" rgba="1 1 1 1" group="0"/>
        <geom name="torso_geom_3" type="mesh" mesh="torso_geom_3_hat_skull" rgba="1 1 1 1" group="0"/>
        <geom name="torso_geom_4" type="mesh" mesh="torso_geom_4_hat_ribs_scap" rgba="1 1 1 1" group="0"/>
        <joint name="lumbar_extension" range="-1.571 1.571" limited="true" user="0.0" ref="0" axis="0 0 1" type="hinge"/>
        <joint name="lumbar_bending" range="-1.571 1.571" limited="true" user="0.0" ref="0" axis="1 0 0" type="hinge"/>
        <joint name="lumbar_rotation" range="-1.571 1.571" limited="true" user="0.0" ref="0" axis="0 1 0" type="hinge"/>
      </body>
      <site name="addbrev_r_addbrev_r-P1" pos="-0.019099999999999999 -0.094 0.0154"/>
      <site name="addlong_r_addlong_r-P1" pos="-0.0075799999999999999 -0.088900000000000007 0.018880000000000001"/>
      <site name="addmagDist_r_addmagDist_r-P1" pos="-0.074039999999999995 -0.12767000000000001 0.039820000000000001"/>
      <site name="addmagIsch_r_addmagIsch_r-P1" pos="-0.089620000000000005 -0.12975999999999999 0.041709999999999997"/>
      <site name="addmagMid_r_addmagMid_r-P1" pos="-0.052659999999999998 -0.12075 0.028539999999999999"/>
      <site name="addmagProx_r_addmagProx_r-P1" pos="-0.030980000000000001 -0.10755000000000001 0.013650000000000001"/>
      <site name="bflh_r_bflh_r-P1" pos="-0.104 -0.1191 0.058599999999999999"/>
      <site name="glmax1_r_glmax1_r-P1" pos="-0.1231 0.034500000000000003 0.056300000000000003"/>
      <site name="glmax1_r_glmax1_r-P2" pos="-0.12570000000000001 -0.024199999999999999 0.077899999999999997"/>
      <site name="Gmax1_at_pelvis_r_cylinder_glmax1_r_2_sidesite" pos="-0.1062 -0.09178 0.1009" size="0.0005"/>
      <site name="glmax2_r_glmax2_r-P1" pos="-0.13170000000000001 0.0086999999999999994 0.046199999999999998"/>
      <site name="glmax2_r_glmax2_r-P2" pos="-0.13439999999999999 -0.060900000000000003 0.081299999999999997"/>
      <site name="Gmax2_at_pelvis_r_cylinder_glmax2_r_2_sidesite" pos="-0.1197 -0.09467 0.0907" size="0.0005"/>
      <site name="glmax3_r_glmax3_r-P1" pos="-0.13 -0.052499999999999998 0.0089999999999999993"/>
      <site name="glmax3_r_glmax3_r-P2" pos="-0.1273 -0.1263 0.043499999999999997"/>
      <site name="Gmax3_at_pelvis_r_cylinder_glmax3_r_1_sidesite" pos="-0.1282 -0.1017 0.032" size="0.0005"/>
      <site name="glmed1_r_glmed1_r-P1" pos="-0.044499999999999998 0.024500000000000001 0.1172"/>
      <site name="glmed2_r_glmed2_r-P1" pos="-0.085000000000000006 0.031600000000000003 0.067500000000000004"/>
      <site name="glmed3_r_glmed3_r-P1" pos="-0.1152 -0.0073000000000000001 0.052600000000000001"/>
      <site name="glmin1_r_glmin1_r-P1" pos="-0.046399999999999997 -0.0149 0.1042"/>
      <site name="glmin2_r_glmin2_r-P1" pos="-0.061600000000000002 -0.014200000000000001 0.097100000000000006"/>
      <site name="glmin3_r_glmin3_r-P1" pos="-0.078899999999999998 -0.0155 0.079799999999999996"/>
      <site name="grac_r_grac_r-P1" pos="-0.047359999999999999 -0.12931999999999999 0.024559999999999998"/>
      <site name="iliacus_r_iliacus_r-P1" pos="-0.060499999999999998 0.0309 0.0843"/>
      <site name="iliacus_r_iliacus_r-P2" pos="-0.0135 -0.0557 0.075600000000000001"/>
      <site name="IL_at_brim_r_cylinder_iliacus_r_2_sidesite" pos="-0.02556 -0.09646 0.08399" size="0.0005"/>
      <site name="piri_r_piri_r-P1" pos="-0.10181 -0.0065300000000000002 0.013509999999999999"/>
      <site name="piri_r_piri_r-P2" pos="-0.10202 -0.03066 0.060920000000000002"/>
      <site name="psoas_r_psoas_r-P1" pos="-0.060600000000000001 0.062 0.039"/>
      <site name="psoas_r_psoas_r-P2" pos="-0.020500000000000001 -0.0654 0.065600000000000006"/>
      <site name="PS_at_brim_r_cylinder_psoas_r_2_sidesite" pos="-0.03216 -0.08851 0.0717" size="0.0005"/>
      <site name="recfem_r_recfem_r-P1" pos="-0.024 -0.038800000000000001 0.093299999999999994"/>
      <site name="sart_r_sart_r-P1" pos="-0.0195 -0.015599999999999999 0.1056"/>
      <site name="semimem_r_semimem_r-P1" pos="-0.098699999999999996 -0.114 0.061400000000000003"/>
      <site name="semiten_r_semiten_r-P1" pos="-0.1038 -0.12529999999999999 0.051499999999999997"/>
      <site name="tfl_r_tfl_r-P1" pos="-0.031099999999999999 0.021399999999999999 0.1241"/>
      <site name="addbrev_l_addbrev_l-P1" pos="-0.019099999999999999 -0.094 -0.0154"/>
      <site name="addlong_l_addlong_l-P1" pos="-0.0075799999999999999 -0.088900000000000007 -0.018880000000000001"/>
      <site name="addmagDist_l_addmagDist_l-P1" pos="-0.074039999999999995 -0.12767000000000001 -0.039820000000000001"/>
      <site name="addmagIsch_l_addmagIsch_l-P1" pos="-0.089620000000000005 -0.12975999999999999 -0.041709999999999997"/>
      <site name="addmagMid_l_addmagMid_l-P1" pos="-0.052659999999999998 -0.12075 -0.028539999999999999"/>
      <site name="addmagProx_l_addmagProx_l-P1" pos="-0.030980000000000001 -0.10755000000000001 -0.013650000000000001"/>
      <site name="bflh_l_bflh_l-P1" pos="-0.104 -0.1191 -0.058599999999999999"/>
      <site name="glmax1_l_glmax1_l-P1" pos="-0.1231 0.034500000000000003 -0.056300000000000003"/>
      <site name="glmax1_l_glmax1_l-P2" pos="-0.12570000000000001 -0.024199999999999999 -0.077899999999999997"/>
      <site name="Gmax1_at_pelvis_l_cylinder_glmax1_l_2_sidesite" pos="-0.1062 -0.09178 -0.1009" size="0.0005"/>
      <site name="glmax2_l_glmax2_l-P1" pos="-0.13170000000000001 0.0086999999999999994 -0.046199999999999998"/>
      <site name="glmax2_l_glmax2_l-P2" pos="-0.13439999999999999 -0.060900000000000003 -0.081299999999999997"/>
      <site name="Gmax2_at_pelvis_l_cylinder_glmax2_l_2_sidesite" pos="-0.1197 -0.09467 -0.0907" size="0.0005"/>
      <site name="glmax3_l_glmax3_l-P1" pos="-0.13 -0.052499999999999998 -0.0089999999999999993"/>
      <site name="glmax3_l_glmax3_l-P2" pos="-0.1273 -0.1263 -0.043499999999999997"/>
      <site name="Gmax3_at_pelvis_l_cylinder_glmax3_l_1_sidesite" pos="-0.1282 -0.1017 -0.032" size="0.0005"/>
      <site name="glmed1_l_glmed1_l-P1" pos="-0.044499999999999998 0.024500000000000001 -0.1172"/>
      <site name="glmed2_l_glmed2_l-P1" pos="-0.085000000000000006 0.031600000000000003 -0.067500000000000004"/>
      <site name="glmed3_l_glmed3_l-P1" pos="-0.1152 -0.0073000000000000001 -0.052600000000000001"/>
      <site name="glmin1_l_glmin1_l-P1" pos="-0.046399999999999997 -0.0149 -0.1042"/>
      <site name="glmin2_l_glmin2_l-P1" pos="-0.061600000000000002 -0.014200000000000001 -0.097100000000000006"/>
      <site name="glmin3_l_glmin3_l-P1" pos="-0.078899999999999998 -0.0155 -0.079799999999999996"/>
      <site name="grac_l_grac_l-P1" pos="-0.047359999999999999 -0.12931999999999999 -0.024559999999999998"/>
      <site name="iliacus_l_iliacus_l-P1" pos="-0.060499999999999998 0.0309 -0.0843"/>
      <site name="iliacus_l_iliacus_l-P2" pos="-0.0135 -0.0557 -0.075600000000000001"/>
      <site name="IL_at_brim_l_cylinder_iliacus_l_2_sidesite" pos="-0.02556 -0.09646 -0.08399" size="0.0005"/>
      <site name="piri_l_piri_l-P1" pos="-0.10181 -0.0065300000000000002 -0.013509999999999999"/>
      <site name="piri_l_piri_l-P2" pos="-0.10202 -0.03066 -0.060920000000000002"/>
      <site name="psoas_l_psoas_l-P1" pos="-0.060600000000000001 0.062 -0.039"/>
      <site name="psoas_l_psoas_l-P2" pos="-0.020500000000000001 -0.0654 -0.065600000000000006"/>
      <site name="PS_at_brim_l_cylinder_psoas_l_2_sidesite" pos="-0.03216 -0.08851 -0.0717" size="0.0005"/>
      <site name="recfem_l_recfem_l-P1" pos="-0.024 -0.038800000000000001 -0.093299999999999994"/>
      <site name="sart_l_sart_l-P1" pos="-0.0195 -0.015599999999999999 -0.1056"/>
      <site name="semimem_l_semimem_l-P1" pos="-0.098699999999999996 -0.114 -0.061400000000000003"/>
      <site name="semiten_l_semiten_l-P1" pos="-0.1038 -0.12529999999999999 -0.051499999999999997"/>
      <site name="tfl_l_tfl_l-P1" pos="-0.031099999999999999 0.021399999999999999 -0.1241"/>
    </body>
  </worldbody>
  <asset>
    <texture type="skybox" builtin="gradient" rgb1="1 1 1" rgb2="0.6 0.8 1" width="256" height="256"/>
    <mesh name="pelvis_geom_1_r_pelvis" file="Geometry/r_pelvis.stl" scale="1 1 1"/>
    <mesh name="pelvis_geom_2_l_pelvis" file="Geometry/l_pelvis.stl" scale="1 1 1"/>
    <mesh name="pelvis_geom_3_sacrum" file="Geometry/sacrum.stl" scale="1 1 1"/>
    <mesh name="femur_r_geom_1_femur_r" file="Geometry/femur_r.stl" scale="1 1 1"/>
    <mesh name="tibia_r_geom_1_tibia_r" file="Geometry/tibia_r.stl" scale="1 1 1"/>
    <mesh name="tibia_r_geom_2_r_fibula" file="Geometry/r_fibula.stl" scale="1 1 1"/>
    <mesh name="talus_r_geom_1_r_talus" file="Geometry/r_talus.stl" scale="1 1 1"/>
    <mesh name="calcn_r_geom_1_r_foot" file="Geometry/r_foot.stl" scale="1 1 1"/>
    <mesh name="toes_r_geom_1_r_bofoot" file="Geometry/r_bofoot.stl" scale="1 1 1"/>
    <mesh name="patella_r_geom_1_r_patella" file="Geometry/r_patella.stl" scale="1 1 1"/>
    <mesh name="femur_l_geom_1_femur_l" file="Geometry/femur_l.stl" scale="1 1 1"/>
    <mesh name="tibia_l_geom_1_l_tib_cut" file="Geometry/l_tib_cut.stl" scale="1 1 1"/>
    <mesh name="tibia_l_geom_2_l_fib_cut" file="Geometry/l_fib_cut.stl" scale="1 1 1"/>
    <mesh name="pylon_l_geom_1_pylon" file="Geometry/pylon.stl" scale="1 1 1"/>
    <mesh name="patella_l_geom_1_l_pat" file="Geometry/l_pat.stl" scale="1 1 1"/>
    <mesh name="torso_geom_1_hat_spine" file="Geometry/hat_spine.stl" scale="1 1 1"/>
    <mesh name="torso_geom_2_hat_jaw" file="Geometry/hat_jaw.stl" scale="1 1 1"/>
    <mesh name="torso_geom_3_hat_skull" file="Geometry/hat_skull.stl" scale="1 1 1"/>
    <mesh name="torso_geom_4_hat_ribs_scap" file="Geometry/hat_ribs_scap.stl" scale="1 1 1"/>
  </asset>
  <tendon>
    <!-- Leave this comment here to make 'tendon' element pretty printed !-->
    <spatial name="addbrev_r_tendon">
      <site site="addbrev_r_addbrev_r-P1"/>
      <geom geom="AB_at_femshaft_r_cylinder" sidesite="AB_at_femshaft_r_cylinder_addbrev_r_1_sidesite"/>
      <site site="addbrev_r_addbrev_r-P2"/>
    </spatial>
    <spatial name="addlong_r_tendon">
      <site site="addlong_r_addlong_r-P1"/>
      <geom geom="AL_at_femshaft_r_cylinder" sidesite="AL_at_femshaft_r_cylinder_addlong_r_1_sidesite"/>
      <site site="addlong_r_addlong_r-P2"/>
    </spatial>
    <spatial name="addmagDist_r_tendon">
      <site site="addmagDist_r_addmagDist_r-P1"/>
      <geom geom="AMdist_at_femshaft_r_cylinder" sidesite="AMdist_at_femshaft_r_cylinder_addmagDist_r_1_sidesite"/>
      <site site="addmagDist_r_addmagDist_r-P2"/>
    </spatial>
    <spatial name="addmagIsch_r_tendon">
      <site site="addmagIsch_r_addmagIsch_r-P1"/>
      <geom geom="AMisch_at_condyles_r_cylinder" sidesite="AMisch_at_condyles_r_cylinder_addmagIsch_r_1_sidesite"/>
      <site site="addmagIsch_r_addmagIsch_r-P2"/>
    </spatial>
    <spatial name="addmagMid_r_tendon">
      <site site="addmagMid_r_addmagMid_r-P1"/>
      <geom geom="AMmid_at_femshaft_r_cylinder" sidesite="AMmid_at_femshaft_r_cylinder_addmagMid_r_1_sidesite"/>
      <site site="addmagMid_r_addmagMid_r-P2"/>
    </spatial>
    <spatial name="addmagProx_r_tendon">
      <site site="addmagProx_r_addmagProx_r-P1"/>
      <geom geom="AMprox_at_femshaft_r_cylinder" sidesite="AMprox_at_femshaft_r_cylinder_addmagProx_r_1_sidesite"/>
      <site site="addmagProx_r_addmagProx_r-P2"/>
    </spatial>
    <spatial name="bflh_r_tendon">
      <site site="bflh_r_bflh_r-P1"/>
      <site site="bflh_r_bflh_r-P2"/>
      <site site="bflh_r_bflh_r-P3"/>
    </spatial>
    <spatial name="bfsh_r_tendon">
      <site site="bfsh_r_bfsh_r-P1"/>
      <site site="bfsh_r_bfsh_r-P2"/>
    </spatial>
    <spatial name="edl_r_tendon">
      <site site="edl_r_edl_r-P1"/>
      <site site="edl_r_edl_r-P2"/>
      <site site="edl_r_edl_r-P3"/>
      <site site="edl_r_edl_r-P4"/>
      <site site="edl_r_edl_r-P5"/>
      <site site="edl_r_edl_r-P6"/>
    </spatial>
    <spatial name="ehl_r_tendon">
      <site site="ehl_r_ehl_r-P1"/>
      <site site="ehl_r_ehl_r-P2"/>
      <site site="ehl_r_ehl_r-P3"/>
      <site site="ehl_r_ehl_r-P4"/>
      <site site="ehl_r_ehl_r-P5"/>
      <site site="ehl_r_ehl_r-P6"/>
      <site site="ehl_r_ehl_r-P7"/>
      <site site="ehl_r_ehl_r-P8"/>
    </spatial>
    <spatial name="fdl_r_tendon">
      <site site="fdl_r_fdl_r-P1"/>
      <site site="fdl_r_fdl_r-P2"/>
      <site site="fdl_r_fdl_r-P3"/>
      <site site="fdl_r_fdl_r-P4"/>
      <site site="fdl_r_fdl_r-P5"/>
      <site site="fdl_r_fdl_r-P6"/>
      <site site="fdl_r_fdl_r-P7"/>
      <site site="fdl_r_fdl_r-P8"/>
    </spatial>
    <spatial name="fhl_r_tendon">
      <site site="fhl_r_fhl_r-P1"/>
      <site site="fhl_r_fhl_r-P2"/>
      <site site="fhl_r_fhl_r-P3"/>
      <site site="fhl_r_fhl_r-P4"/>
      <site site="fhl_r_fhl_r-P5"/>
      <site site="fhl_r_fhl_r-P6"/>
      <site site="fhl_r_fhl_r-P7"/>
    </spatial>
    <spatial name="gaslat_r_tendon">
      <site site="gaslat_r_gaslat_r-P1"/>
      <geom geom="Gastroc_at_condyles_r_cylinder" sidesite="Gastroc_at_condyles_r_cylinder_gaslat_r_1_sidesite"/>
      <site site="gaslat_r_gaslat_r-P2"/>
    </spatial>
    <spatial name="gasmed_r_tendon">
      <site site="gasmed_r_gasmed_r-P1"/>
      <geom geom="Gastroc_at_condyles_r_cylinder" sidesite="Gastroc_at_condyles_r_cylinder_gasmed_r_1_sidesite"/>
      <site site="gasmed_r_gasmed_r-P2"/>
    </spatial>
    <spatial name="glmax1_r_tendon">
      <site site="glmax1_r_glmax1_r-P1"/>
      <site site="glmax1_r_glmax1_r-P2"/>
      <geom geom="Gmax1_at_pelvis_r_cylinder" sidesite="Gmax1_at_pelvis_r_cylinder_glmax1_r_2_sidesite"/>
      <site site="glmax1_r_glmax1_r-P3"/>
      <site site="glmax1_r_glmax1_r-P4"/>
    </spatial>
    <spatial name="glmax2_r_tendon">
      <site site="glmax2_r_glmax2_r-P1"/>
      <site site="glmax2_r_glmax2_r-P2"/>
      <geom geom="Gmax2_at_pelvis_r_cylinder" sidesite="Gmax2_at_pelvis_r_cylinder_glmax2_r_2_sidesite"/>
      <site site="glmax2_r_glmax2_r-P3"/>
      <site site="glmax2_r_glmax2_r-P4"/>
    </spatial>
    <spatial name="glmax3_r_tendon">
      <site site="glmax3_r_glmax3_r-P1"/>
      <geom geom="Gmax3_at_pelvis_r_cylinder" sidesite="Gmax3_at_pelvis_r_cylinder_glmax3_r_1_sidesite"/>
      <site site="glmax3_r_glmax3_r-P2"/>
      <site site="glmax3_r_glmax3_r-P3"/>
      <site site="glmax3_r_glmax3_r-P4"/>
    </spatial>
    <spatial name="glmed1_r_tendon">
      <site site="glmed1_r_glmed1_r-P1"/>
      <site site="glmed1_r_glmed1_r-P2"/>
    </spatial>
    <spatial name="glmed2_r_tendon">
      <site site="glmed2_r_glmed2_r-P1"/>
      <site site="glmed2_r_glmed2_r-P2"/>
    </spatial>
    <spatial name="glmed3_r_tendon">
      <site site="glmed3_r_glmed3_r-P1"/>
      <site site="glmed3_r_glmed3_r-P2"/>
    </spatial>
    <spatial name="glmin1_r_tendon">
      <site site="glmin1_r_glmin1_r-P1"/>
      <site site="glmin1_r_glmin1_r-P2"/>
    </spatial>
    <spatial name="glmin2_r_tendon">
      <site site="glmin2_r_glmin2_r-P1"/>
      <site site="glmin2_r_glmin2_r-P2"/>
    </spatial>
    <spatial name="glmin3_r_tendon">
      <site site="glmin3_r_glmin3_r-P1"/>
      <site site="glmin3_r_glmin3_r-P2"/>
    </spatial>
    <spatial name="grac_r_tendon">
      <site site="grac_r_grac_r-P1"/>
      <geom geom="GR_at_condyles_r_cylinder" sidesite="GR_at_condyles_r_cylinder_grac_r_1_sidesite"/>
      <site site="grac_r_grac_r-P2"/>
      <site site="grac_r_grac_r-P3"/>
    </spatial>
    <spatial name="iliacus_r_tendon">
      <site site="iliacus_r_iliacus_r-P1"/>
      <site site="iliacus_r_iliacus_r-P2"/>
      <geom geom="IL_at_brim_r_cylinder" sidesite="IL_at_brim_r_cylinder_iliacus_r_2_sidesite"/>
      <site site="iliacus_r_iliacus_r-P3"/>
      <site site="iliacus_r_iliacus_r-P4"/>
    </spatial>
    <spatial name="perbrev_r_tendon">
      <site site="perbrev_r_perbrev_r-P1"/>
      <site site="perbrev_r_perbrev_r-P2"/>
      <site site="perbrev_r_perbrev_r-P3"/>
      <site site="perbrev_r_perbrev_r-P4"/>
      <site site="perbrev_r_perbrev_r-P5"/>
    </spatial>
    <spatial name="perlong_r_tendon">
      <site site="perlong_r_perlong_r-P1"/>
      <site site="perlong_r_perlong_r-P2"/>
      <site site="perlong_r_perlong_r-P3"/>
      <site site="perlong_r_perlong_r-P4"/>
      <site site="perlong_r_perlong_r-P5"/>
      <site site="perlong_r_perlong_r-P6"/>
      <site site="perlong_r_perlong_r-P7"/>
    </spatial>
    <spatial name="piri_r_tendon">
      <site site="piri_r_piri_r-P1"/>
      <site site="piri_r_piri_r-P2"/>
      <site site="piri_r_piri_r-P3"/>
    </spatial>
    <spatial name="psoas_r_tendon">
      <site site="psoas_r_psoas_r-P1"/>
      <site site="psoas_r_psoas_r-P2"/>
      <geom geom="PS_at_brim_r_cylinder" sidesite="PS_at_brim_r_cylinder_psoas_r_2_sidesite"/>
      <site site="psoas_r_psoas_r-P3"/>
      <site site="psoas_r_psoas_r-P4"/>
    </spatial>
    <spatial name="recfem_r_tendon">
      <site site="recfem_r_recfem_r-P1"/>
      <site site="recfem_r_recfem_r-P2"/>
      <site site="recfem_r_recfem_r-P3"/>
      <geom geom="KnExt_at_fem_r_cylinder" sidesite="KnExt_at_fem_r_cylinder_recfem_r_3_sidesite"/>
      <site site="recfem_r_recfem_r-P4"/>
      <site site="recfem_r_recfem_r-P5"/>
    </spatial>
    <spatial name="sart_r_tendon">
      <site site="sart_r_sart_r-P1"/>
      <site site="sart_r_sart_r-P2"/>
      <site site="sart_r_sart_r-P3"/>
      <site site="sart_r_sart_r-P4"/>
      <site site="sart_r_sart_r-P5"/>
    </spatial>
    <spatial name="semimem_r_tendon">
      <site site="semimem_r_semimem_r-P1"/>
      <geom geom="SM_at_condyles_r_cylinder" sidesite="SM_at_condyles_r_cylinder_semimem_r_1_sidesite"/>
      <site site="semimem_r_semimem_r-P2"/>
    </spatial>
    <spatial name="semiten_r_tendon">
      <site site="semiten_r_semiten_r-P1"/>
      <geom geom="ST_at_condyles_r_cylinder" sidesite="ST_at_condyles_r_cylinder_semiten_r_1_sidesite"/>
      <site site="semiten_r_semiten_r-P2"/>
      <site site="semiten_r_semiten_r-P3"/>
    </spatial>
    <spatial name="soleus_r_tendon">
      <site site="soleus_r_soleus_r-P1"/>
      <site site="soleus_r_soleus_r-P2"/>
    </spatial>
    <spatial name="tfl_r_tendon">
      <site site="tfl_r_tfl_r-P1"/>
      <site site="tfl_r_tfl_r-P2"/>
      <site site="tfl_r_tfl_r-P3"/>
      <site site="tfl_r_tfl_r-P4"/>
    </spatial>
    <spatial name="tibant_r_tendon">
      <site site="tibant_r_tibant_r-P1"/>
      <site site="tibant_r_tibant_r-P2"/>
      <site site="tibant_r_tibant_r-P3"/>
      <site site="tibant_r_tibant_r-P4"/>
    </spatial>
    <spatial name="tibpost_r_tendon">
      <site site="tibpost_r_tibpost_r-P1"/>
      <site site="tibpost_r_tibpost_r-P2"/>
      <site site="tibpost_r_tibpost_r-P3"/>
      <site site="tibpost_r_tibpost_r-P4"/>
    </spatial>
    <spatial name="vasint_r_tendon">
      <site site="vasint_r_vasint_r-P1"/>
      <site site="vasint_r_vasint_r-P2"/>
      <site site="vasint_r_vasint_r-P3"/>
      <geom geom="KnExt_at_fem_r_cylinder" sidesite="KnExt_at_fem_r_cylinder_vasint_r_3_sidesite"/>
      <site site="vasint_r_vasint_r-P4"/>
      <site site="vasint_r_vasint_r-P5"/>
    </spatial>
    <spatial name="vaslat_r_tendon">
      <site site="vaslat_r_vaslat_r-P1"/>
      <site site="vaslat_r_vaslat_r-P2"/>
      <site site="vaslat_r_vaslat_r-P3"/>
      <geom geom="KnExt_at_fem_r_cylinder" sidesite="KnExt_at_fem_r_cylinder_vaslat_r_3_sidesite"/>
      <site site="vaslat_r_vaslat_r-P4"/>
      <site site="vaslat_r_vaslat_r-P5"/>
    </spatial>
    <spatial name="vasmed_r_tendon">
      <site site="vasmed_r_vasmed_r-P1"/>
      <site site="vasmed_r_vasmed_r-P2"/>
      <site site="vasmed_r_vasmed_r-P3"/>
      <geom geom="KnExt_at_fem_r_cylinder" sidesite="KnExt_at_fem_r_cylinder_vasmed_r_3_sidesite"/>
      <site site="vasmed_r_vasmed_r-P4"/>
      <geom geom="KnExt_at_fem_r_cylinder" sidesite="KnExt_at_fem_r_cylinder_vasmed_r_4_sidesite"/>
      <site site="vasmed_r_vasmed_r-P5"/>
    </spatial>
    <spatial name="addbrev_l_tendon">
      <site site="addbrev_l_addbrev_l-P1"/>
      <geom geom="AB_at_femshaft_l_cylinder" sidesite="AB_at_femshaft_l_cylinder_addbrev_l_1_sidesite"/>
      <site site="addbrev_l_addbrev_l-P2"/>
    </spatial>
    <spatial name="addlong_l_tendon">
      <site site="addlong_l_addlong_l-P1"/>
      <geom geom="AL_at_femshaft_l_cylinder" sidesite="AL_at_femshaft_l_cylinder_addlong_l_1_sidesite"/>
      <site site="addlong_l_addlong_l-P2"/>
    </spatial>
    <spatial name="addmagDist_l_tendon">
      <site site="addmagDist_l_addmagDist_l-P1"/>
      <geom geom="AMdist_at_femshaft_l_cylinder" sidesite="AMdist_at_femshaft_l_cylinder_addmagDist_l_1_sidesite"/>
      <site site="addmagDist_l_addmagDist_l-P2"/>
    </spatial>
    <spatial name="addmagIsch_l_tendon">
      <site site="addmagIsch_l_addmagIsch_l-P1"/>
      <geom geom="AMisch_at_condyles_l_cylinder" sidesite="AMisch_at_condyles_l_cylinder_addmagIsch_l_1_sidesite"/>
      <site site="addmagIsch_l_addmagIsch_l-P2"/>
    </spatial>
    <spatial name="addmagMid_l_tendon">
      <site site="addmagMid_l_addmagMid_l-P1"/>
      <geom geom="AMmid_at_femshaft_l_cylinder" sidesite="AMmid_at_femshaft_l_cylinder_addmagMid_l_1_sidesite"/>
      <site site="addmagMid_l_addmagMid_l-P2"/>
    </spatial>
    <spatial name="addmagProx_l_tendon">
      <site site="addmagProx_l_addmagProx_l-P1"/>
      <geom geom="AMprox_at_femshaft_l_cylinder" sidesite="AMprox_at_femshaft_l_cylinder_addmagProx_l_1_sidesite"/>
      <site site="addmagProx_l_addmagProx_l-P2"/>
    </spatial>
    <spatial name="bflh_l_tendon">
      <site site="bflh_l_bflh_l-P1"/>
      <site site="bflh_l_bflh_l-P2"/>
      <site site="bflh_l_bflh_l-P3"/>
    </spatial>
    <spatial name="bfsh_l_tendon">
      <site site="bfsh_l_bfsh_l-P1"/>
      <site site="bfsh_l_bfsh_l-P2"/>
    </spatial>
    <spatial name="glmax1_l_tendon">
      <site site="glmax1_l_glmax1_l-P1"/>
      <site site="glmax1_l_glmax1_l-P2"/>
      <geom geom="Gmax1_at_pelvis_l_cylinder" sidesite="Gmax1_at_pelvis_l_cylinder_glmax1_l_2_sidesite"/>
      <site site="glmax1_l_glmax1_l-P3"/>
      <site site="glmax1_l_glmax1_l-P4"/>
    </spatial>
    <spatial name="glmax2_l_tendon">
      <site site="glmax2_l_glmax2_l-P1"/>
      <site site="glmax2_l_glmax2_l-P2"/>
      <geom geom="Gmax2_at_pelvis_l_cylinder" sidesite="Gmax2_at_pelvis_l_cylinder_glmax2_l_2_sidesite"/>
      <site site="glmax2_l_glmax2_l-P3"/>
      <site site="glmax2_l_glmax2_l-P4"/>
    </spatial>
    <spatial name="glmax3_l_tendon">
      <site site="glmax3_l_glmax3_l-P1"/>
      <geom geom="Gmax3_at_pelvis_l_cylinder" sidesite="Gmax3_at_pelvis_l_cylinder_glmax3_l_1_sidesite"/>
      <site site="glmax3_l_glmax3_l-P2"/>
      <site site="glmax3_l_glmax3_l-P3"/>
      <site site="glmax3_l_glmax3_l-P4"/>
    </spatial>
    <spatial name="glmed1_l_tendon">
      <site site="glmed1_l_glmed1_l-P1"/>
      <site site="glmed1_l_glmed1_l-P2"/>
    </spatial>
    <spatial name="glmed2_l_tendon">
      <site site="glmed2_l_glmed2_l-P1"/>
      <site site="glmed2_l_glmed2_l-P2"/>
    </spatial>
    <spatial name="glmed3_l_tendon">
      <site site="glmed3_l_glmed3_l-P1"/>
      <site site="glmed3_l_glmed3_l-P2"/>
    </spatial>
    <spatial name="glmin1_l_tendon">
      <site site="glmin1_l_glmin1_l-P1"/>
      <site site="glmin1_l_glmin1_l-P2"/>
    </spatial>
    <spatial name="glmin2_l_tendon">
      <site site="glmin2_l_glmin2_l-P1"/>
      <site site="glmin2_l_glmin2_l-P2"/>
    </spatial>
    <spatial name="glmin3_l_tendon">
      <site site="glmin3_l_glmin3_l-P1"/>
      <site site="glmin3_l_glmin3_l-P2"/>
    </spatial>
    <spatial name="grac_l_tendon">
      <site site="grac_l_grac_l-P1"/>
      <geom geom="GR_at_condyles_l_cylinder" sidesite="GR_at_condyles_l_cylinder_grac_l_1_sidesite"/>
      <site site="grac_l_grac_l-P2"/>
      <site site="grac_l_grac_l-P3"/>
    </spatial>
    <spatial name="iliacus_l_tendon">
      <site site="iliacus_l_iliacus_l-P1"/>
      <site site="iliacus_l_iliacus_l-P2"/>
      <geom geom="IL_at_brim_l_cylinder" sidesite="IL_at_brim_l_cylinder_iliacus_l_2_sidesite"/>
      <site site="iliacus_l_iliacus_l-P3"/>
      <site site="iliacus_l_iliacus_l-P4"/>
    </spatial>
    <spatial name="piri_l_tendon">
      <site site="piri_l_piri_l-P1"/>
      <site site="piri_l_piri_l-P2"/>
      <site site="piri_l_piri_l-P3"/>
    </spatial>
    <spatial name="psoas_l_tendon">
      <site site="psoas_l_psoas_l-P1"/>
      <site site="psoas_l_psoas_l-P2"/>
      <geom geom="PS_at_brim_l_cylinder" sidesite="PS_at_brim_l_cylinder_psoas_l_2_sidesite"/>
      <site site="psoas_l_psoas_l-P3"/>
      <site site="psoas_l_psoas_l-P4"/>
    </spatial>
    <spatial name="recfem_l_tendon">
      <site site="recfem_l_recfem_l-P1"/>
      <site site="recfem_l_recfem_l-P2"/>
      <site site="recfem_l_recfem_l-P3"/>
      <geom geom="KnExt_at_fem_l_cylinder" sidesite="KnExt_at_fem_l_cylinder_recfem_l_3_sidesite"/>
      <site site="recfem_l_recfem_l-P4"/>
      <site site="recfem_l_recfem_l-P5"/>
    </spatial>
    <spatial name="sart_l_tendon">
      <site site="sart_l_sart_l-P1"/>
      <site site="sart_l_sart_l-P2"/>
      <site site="sart_l_sart_l-P3"/>
      <site site="sart_l_sart_l-P4"/>
      <site site="sart_l_sart_l-P5"/>
    </spatial>
    <spatial name="semimem_l_tendon">
      <site site="semimem_l_semimem_l-P1"/>
      <geom geom="SM_at_condyles_l_cylinder" sidesite="SM_at_condyles_l_cylinder_semimem_l_1_sidesite"/>
      <site site="semimem_l_semimem_l-P2"/>
    </spatial>
    <spatial name="semiten_l_tendon">
      <site site="semiten_l_semiten_l-P1"/>
      <geom geom="ST_at_condyles_l_cylinder" sidesite="ST_at_condyles_l_cylinder_semiten_l_1_sidesite"/>
      <site site="semiten_l_semiten_l-P2"/>
      <site site="semiten_l_semiten_l-P3"/>
    </spatial>
    <spatial name="tfl_l_tendon">
      <site site="tfl_l_tfl_l-P1"/>
      <site site="tfl_l_tfl_l-P2"/>
      <site site="tfl_l_tfl_l-P3"/>
      <site site="tfl_l_tfl_l-P4"/>
    </spatial>
    <spatial name="vasint_l_tendon">
      <site site="vasint_l_vasint_l-P1"/>
      <site site="vasint_l_vasint_l-P2"/>
      <site site="vasint_l_vasint_l-P3"/>
      <geom geom="KnExt_at_fem_l_cylinder" sidesite="KnExt_at_fem_l_cylinder_vasint_l_3_sidesite"/>
      <site site="vasint_l_vasint_l-P4"/>
      <site site="vasint_l_vasint_l-P5"/>
    </spatial>
    <spatial name="vaslat_l_tendon">
      <site site="vaslat_l_vaslat_l-P1"/>
      <site site="vaslat_l_vaslat_l-P2"/>
      <site site="vaslat_l_vaslat_l-P3"/>
      <geom geom="KnExt_at_fem_l_cylinder" sidesite="KnExt_at_fem_l_cylinder_vaslat_l_3_sidesite"/>
      <site site="vaslat_l_vaslat_l-P4"/>
      <site site="vaslat_l_vaslat_l-P5"/>
    </spatial>
    <spatial name="vasmed_l_tendon">
      <site site="vasmed_l_vasmed_l-P1"/>
      <site site="vasmed_l_vasmed_l-P2"/>
      <site site="vasmed_l_vasmed_l-P3"/>
      <geom geom="KnExt_at_fem_l_cylinder" sidesite="KnExt_at_fem_l_cylinder_vasmed_l_3_sidesite"/>
      <site site="vasmed_l_vasmed_l-P4"/>
      <geom geom="KnExt_at_fem_l_cylinder" sidesite="KnExt_at_fem_l_cylinder_vasmed_l_4_sidesite"/>
      <site site="vasmed_l_vasmed_l-P5"/>
    </spatial>
  </tendon>
  <actuator>
    <!-- Leave this comment here to make 'actuator' element pretty printed !-->
    <muscle name="addbrev_r" lengthrange="0.01 1" force="625.81967213114797" tendon="addbrev_r_tendon" class="muscle" timeconst="0.01 0.04"/>
    <muscle name="addlong_r" lengthrange="0.01 1" force="916.79999999999995" tendon="addlong_r_tendon" class="muscle" timeconst="0.01 0.04"/>
    <muscle name="addmagDist_r" lengthrange="0.01 1" force="597.29508196721395" tendon="addmagDist_r_tendon" class="muscle" timeconst="0.01 0.04"/>
    <muscle name="addmagIsch_r" lengthrange="0.01 1" force="597.29508196721395" tendon="addmagIsch_r_tendon" class="muscle" timeconst="0.01 0.04"/>
    <muscle name="addmagMid_r" lengthrange="0.01 1" force="597.29508196721395" tendon="addmagMid_r_tendon" class="muscle" timeconst="0.01 0.04"/>
    <muscle name="addmagProx_r" lengthrange="0.01 1" force="597.29508196721395" tendon="addmagProx_r_tendon" class="muscle" timeconst="0.01 0.04"/>
    <muscle name="bflh_r" lengthrange="0.01 1" force="1313.18360655738" tendon="bflh_r_tendon" class="muscle" timeconst="0.01 0.04"/>
    <muscle name="bfsh_r" lengthrange="0.01 1" force="557.11475409835998" tendon="bfsh_r_tendon" class="muscle" timeconst="0.01 0.04"/>
    <muscle name="edl_r" lengthrange="0.01 1" force="603.49815560000002" tendon="edl_r_tendon" class="muscle" timeconst="0.01 0.04"/>
    <muscle name="ehl_r" lengthrange="0.01 1" force="285.86754739999998" tendon="ehl_r_tendon" class="muscle" timeconst="0.01 0.04"/>
    <muscle name="fdl_r" lengthrange="0.01 1" force="423.17704918032803" tendon="fdl_r_tendon" class="muscle" timeconst="0.01 0.04"/>
    <muscle name="fhl_r" lengthrange="0.01 1" force="907.83934426229405" tendon="fhl_r_tendon" class="muscle" timeconst="0.01 0.04"/>
    <muscle name="gaslat_r" lengthrange="0.01 1" force="1575.0590163934401" tendon="gaslat_r_tendon" class="muscle" timeconst="0.01 0.04"/>
    <muscle name="gasmed_r" lengthrange="0.01 1" force="3115.5147540983598" tendon="gasmed_r_tendon" class="muscle" timeconst="0.01 0.04"/>
    <muscle name="glmax1_r" lengthrange="0.01 1" force="983.78360655737799" tendon="glmax1_r_tendon" class="muscle" timeconst="0.01 0.04"/>
    <muscle name="glmax2_r" lengthrange="0.01 1" force="1406.0459016393499" tendon="glmax2_r_tendon" class="muscle" timeconst="0.01 0.04"/>
    <muscle name="glmax3_r" lengthrange="0.01 1" force="947.75409836065603" tendon="glmax3_r_tendon" class="muscle" timeconst="0.01 0.04"/>
    <muscle name="glmed1_r" lengthrange="0.01 1" force="1093.4667688" tendon="glmed1_r_tendon" class="muscle" timeconst="0.01 0.04"/>
    <muscle name="glmed2_r" lengthrange="0.01 1" force="765.09166159999995" tendon="glmed2_r_tendon" class="muscle" timeconst="0.01 0.04"/>
    <muscle name="glmed3_r" lengthrange="0.01 1" force="871.19926420000002" tendon="glmed3_r_tendon" class="muscle" timeconst="0.01 0.04"/>
    <muscle name="glmin1_r" lengthrange="0.01 1" force="374.04590163934398" tendon="glmin1_r_tendon" class="muscle" timeconst="0.01 0.04"/>
    <muscle name="glmin2_r" lengthrange="0.01 1" force="394.81967213114802" tendon="glmin2_r_tendon" class="muscle" timeconst="0.01 0.04"/>
    <muscle name="glmin3_r" lengthrange="0.01 1" force="446.77377049180399" tendon="glmin3_r_tendon" class="muscle" timeconst="0.01 0.04"/>
    <muscle name="grac_r" lengthrange="0.01 1" force="281.31147540983602" tendon="grac_r_tendon" class="muscle" timeconst="0.01 0.04"/>
    <muscle name="iliacus_r" lengthrange="0.01 1" force="1021.14098360656" tendon="iliacus_r_tendon" class="muscle" timeconst="0.01 0.04"/>
    <muscle name="perbrev_r" lengthrange="0.01 1" force="521.20159880000006" tendon="perbrev_r_tendon" class="muscle" timeconst="0.01 0.04"/>
    <muscle name="perlong_r" lengthrange="0.01 1" force="1115.3714213999999" tendon="perlong_r_tendon" class="muscle" timeconst="0.01 0.04"/>
    <muscle name="piri_r" lengthrange="0.01 1" force="1029.7868852459001" tendon="piri_r_tendon" class="muscle" timeconst="0.01 0.04"/>
    <muscle name="psoas_r" lengthrange="0.01 1" force="1426.79016393443" tendon="psoas_r_tendon" class="muscle" timeconst="0.01 0.04"/>
    <muscle name="recfem_r" lengthrange="0.01 1" force="2191.7409836065599" tendon="recfem_r_tendon" class="muscle" timeconst="0.01 0.04"/>
    <muscle name="sart_r" lengthrange="0.01 1" force="249.41311475409799" tendon="sart_r_tendon" class="muscle" timeconst="0.01 0.04"/>
    <muscle name="semimem_r" lengthrange="0.01 1" force="2200.9868852458999" tendon="semimem_r_tendon" class="muscle" timeconst="0.01 0.04"/>
    <muscle name="semiten_r" lengthrange="0.01 1" force="591.29508196721395" tendon="semiten_r_tendon" class="muscle" timeconst="0.01 0.04"/>
    <muscle name="soleus_r" lengthrange="0.01 1" force="6194.8426229508204" tendon="soleus_r_tendon" class="muscle" timeconst="0.01 0.04"/>
    <muscle name="tfl_r" lengthrange="0.01 1" force="411.20655737704999" tendon="tfl_r_tendon" class="muscle" timeconst="0.01 0.04"/>
    <muscle name="tibant_r" lengthrange="0.01 1" force="1227.4524590163901" tendon="tibant_r_tendon" class="muscle" timeconst="0.01 0.04"/>
    <muscle name="tibpost_r" lengthrange="0.01 1" force="1730.1540983606501" tendon="tibpost_r_tendon" class="muscle" timeconst="0.01 0.04"/>
    <muscle name="vasint_r" lengthrange="0.01 1" force="1697.36065573771" tendon="vasint_r_tendon" class="muscle" timeconst="0.01 0.04"/>
    <muscle name="vaslat_r" lengthrange="0.01 1" force="5148.7672131147601" tendon="vaslat_r_tendon" class="muscle" timeconst="0.01 0.04"/>
    <muscle name="vasmed_r" lengthrange="0.01 1" force="2747.82295081966" tendon="vasmed_r_tendon" class="muscle" timeconst="0.01 0.04"/>
    <muscle name="addbrev_l" lengthrange="0.01 1" force="625.81967213114797" tendon="addbrev_l_tendon" class="muscle" timeconst="0.01 0.04"/>
    <muscle name="addlong_l" lengthrange="0.01 1" force="916.79999999999995" tendon="addlong_l_tendon" class="muscle" timeconst="0.01 0.04"/>
    <muscle name="addmagDist_l" lengthrange="0.01 1" force="597.29508196721395" tendon="addmagDist_l_tendon" class="muscle" timeconst="0.01 0.04"/>
    <muscle name="addmagIsch_l" lengthrange="0.01 1" force="597.29508196721395" tendon="addmagIsch_l_tendon" class="muscle" timeconst="0.01 0.04"/>
    <muscle name="addmagMid_l" lengthrange="0.01 1" force="597.29508196721395" tendon="addmagMid_l_tendon" class="muscle" timeconst="0.01 0.04"/>
    <muscle name="addmagProx_l" lengthrange="0.01 1" force="597.29508196721395" tendon="addmagProx_l_tendon" class="muscle" timeconst="0.01 0.04"/>
    <muscle name="bflh_l" lengthrange="0.01 1" force="1313.18360655738" tendon="bflh_l_tendon" class="muscle" timeconst="0.01 0.04"/>
    <muscle name="bfsh_l" lengthrange="0.01 1" force="557.11475409835998" tendon="bfsh_l_tendon" class="muscle" timeconst="0.01 0.04"/>
    <muscle name="glmax1_l" lengthrange="0.01 1" force="983.78360655737799" tendon="glmax1_l_tendon" class="muscle" timeconst="0.01 0.04"/>
    <muscle name="glmax2_l" lengthrange="0.01 1" force="1406.0459016393499" tendon="glmax2_l_tendon" class="muscle" timeconst="0.01 0.04"/>
    <muscle name="glmax3_l" lengthrange="0.01 1" force="947.75409836065603" tendon="glmax3_l_tendon" class="muscle" timeconst="0.01 0.04"/>
    <muscle name="glmed1_l" lengthrange="0.01 1" force="1093.4667688" tendon="glmed1_l_tendon" class="muscle" timeconst="0.01 0.04"/>
    <muscle name="glmed2_l" lengthrange="0.01 1" force="765.09166159999995" tendon="glmed2_l_tendon" class="muscle" timeconst="0.01 0.04"/>
    <muscle name="glmed3_l" lengthrange="0.01 1" force="871.19926420000002" tendon="glmed3_l_tendon" class="muscle" timeconst="0.01 0.04"/>
    <muscle name="glmin1_l" lengthrange="0.01 1" force="374.04590163934398" tendon="glmin1_l_tendon" class="muscle" timeconst="0.01 0.04"/>
    <muscle name="glmin2_l" lengthrange="0.01 1" force="394.81967213114802" tendon="glmin2_l_tendon" class="muscle" timeconst="0.01 0.04"/>
    <muscle name="glmin3_l" lengthrange="0.01 1" force="446.77377049180399" tendon="glmin3_l_tendon" class="muscle" timeconst="0.01 0.04"/>
    <muscle name="grac_l" lengthrange="0.01 1" force="281.31147540983602" tendon="grac_l_tendon" class="muscle" timeconst="0.01 0.04"/>
    <muscle name="iliacus_l" lengthrange="0.01 1" force="1021.14098360656" tendon="iliacus_l_tendon" class="muscle" timeconst="0.01 0.04"/>
    <muscle name="piri_l" lengthrange="0.01 1" force="1029.7868852459001" tendon="piri_l_tendon" class="muscle" timeconst="0.01 0.04"/>
    <muscle name="psoas_l" lengthrange="0.01 1" force="1426.79016393443" tendon="psoas_l_tendon" class="muscle" timeconst="0.01 0.04"/>
    <muscle name="recfem_l" lengthrange="0.01 1" force="2191.7409836065599" tendon="recfem_l_tendon" class="muscle" timeconst="0.01 0.04"/>
    <muscle name="sart_l" lengthrange="0.01 1" force="249.41311475409799" tendon="sart_l_tendon" class="muscle" timeconst="0.01 0.04"/>
    <muscle name="semimem_l" lengthrange="0.01 1" force="2200.9868852458999" tendon="semimem_l_tendon" class="muscle" timeconst="0.01 0.04"/>
    <muscle name="semiten_l" lengthrange="0.01 1" force="591.29508196721395" tendon="semiten_l_tendon" class="muscle" timeconst="0.01 0.04"/>
    <muscle name="tfl_l" lengthrange="0.01 1" force="411.20655737704999" tendon="tfl_l_tendon" class="muscle" timeconst="0.01 0.04"/>
    <muscle name="vasint_l" lengthrange="0.01 1" force="1697.36065573771" tendon="vasint_l_tendon" class="muscle" timeconst="0.01 0.04"/>
    <muscle name="vaslat_l" lengthrange="0.01 1" force="5148.7672131147601" tendon="vaslat_l_tendon" class="muscle" timeconst="0.01 0.04"/>
    <muscle name="vasmed_l" lengthrange="0.01 1" force="2747.82295081966" tendon="vasmed_l_tendon" class="muscle" timeconst="0.01 0.04"/>
  </actuator>
  <equality>
    <!-- Leave this comment here to make 'equality' element pretty printed !-->
    <joint joint1="walker_knee_r_translation1" joint2="knee_angle_r" polycoef="9.537e-08 0.003129 -0.002308 0.0005616 5.684e-07" solimp="0.9999 0.9999 0.001 0.5 2" active="true"/>
    <joint joint1="walker_knee_r_translation2" joint2="knee_angle_r" polycoef="7.693e-11 0.00588 -0.001256 -2.618e-06 6.244e-07" solimp="0.9999 0.9999 0.001 0.5 2" active="true"/>
    <joint joint1="walker_knee_r_rotation2" joint2="knee_angle_r" polycoef="-1.473e-08 0.0791 -0.03285 -0.02522 0.01083" solimp="0.9999 0.9999 0.001 0.5 2" active="true"/>
    <joint joint1="walker_knee_r_rotation3" joint2="knee_angle_r" polycoef="1.089e-08 0.3695 -0.1695 0.02516 3.505e-07" solimp="0.9999 0.9999 0.001 0.5 2" active="true"/>
    <joint name="subtalar_angle_r_locked" active="true" joint1="subtalar_angle_r" polycoef="0.0 0 0 0 0" solimp="0.9999 0.9999 0.001 0.5 2"/>
    <joint name="mtp_angle_r_locked" active="true" joint1="mtp_angle_r" polycoef="0.0 0 0 0 0" solimp="0.9999 0.9999 0.001 0.5 2"/>
    <joint joint1="patellofemoral_r_translation1" joint2="knee_angle_r" polycoef="0.05242 -0.01502 -0.03405 0.01334 -0.0008792" solimp="0.9999 0.9999 0.001 0.5 2" active="true"/>
    <joint joint1="patellofemoral_r_translation2" joint2="knee_angle_r" polycoef="-0.01083 -0.04878 0.009276 0.01317 -0.003497" solimp="0.9999 0.9999 0.001 0.5 2" active="true"/>
    <joint joint1="patellofemoral_r_rotation1" joint2="knee_angle_r" polycoef="0.01051 0.02476 -1.316 0.7163 -0.1383" solimp="0.9999 0.9999 0.001 0.5 2" active="true"/>
    <joint name="patellofemoral_r_translation3_locked" active="true" joint1="patellofemoral_r_translation3" polycoef="0.00275 0 0 0 0" solimp="0.9999 0.9999 0.001 0.5 2"/>
    <joint joint1="walker_knee_l_translation1" joint2="knee_angle_l" polycoef="9.537e-08 0.003129 -0.002308 0.0005616 5.684e-07" solimp="0.9999 0.9999 0.001 0.5 2" active="true"/>
    <joint joint1="walker_knee_l_translation2" joint2="knee_angle_l" polycoef="-7.693e-11 -0.00588 0.001256 2.618e-06 -6.244e-07" solimp="0.9999 0.9999 0.001 0.5 2" active="true"/>
    <joint joint1="walker_knee_l_rotation2" joint2="knee_angle_l" polycoef="-1.473e-08 0.0791 -0.03285 -0.02522 0.01083" solimp="0.9999 0.9999 0.001 0.5 2" active="true"/>
    <joint joint1="walker_knee_l_rotation3" joint2="knee_angle_l" polycoef="-1.089e-08 -0.3695 0.1695 -0.02516 -3.505e-07" solimp="0.9999 0.9999 0.001 0.5 2" active="true"/>
    <joint name="socket_piston_l_locked" active="true" joint1="socket_piston_l" polycoef="0.0 0 0 0 0" solimp="0.9999 0.9999 0.001 0.5 2"/>
    <joint name="socket_rotation_l_locked" active="true" joint1="socket_rotation_l" polycoef="0.0 0 0 0 0" solimp="0.9999 0.9999 0.001 0.5 2"/>
    <joint name="SP_rotation_l_locked" active="true" joint1="SP_rotation_l" polycoef="0.0 0 0 0 0" solimp="0.9999 0.9999 0.001 0.5 2"/>
    <joint name="ankle_ext_rot_l_locked" active="true" joint1="ankle_ext_rot_l" polycoef="0.174532478855694 0 0 0 0" solimp="0.9999 0.9999 0.001 0.5 2"/>
    <joint joint1="patellofemoral_l_translation1" joint2="knee_angle_l" polycoef="0.05242 -0.01502 -0.03405 0.01334 -0.0008792" solimp="0.9999 0.9999 0.001 0.5 2" active="true"/>
    <joint joint1="patellofemoral_l_translation2" joint2="knee_angle_l" polycoef="-0.01083 -0.04878 0.009276 0.01317 -0.003497" solimp="0.9999 0.9999 0.001 0.5 2" active="true"/>
    <joint joint1="patellofemoral_l_rotation1" joint2="knee_angle_l" polycoef="0.01051 0.02476 -1.316 0.7163 -0.1383" solimp="0.9999 0.9999 0.001 0.5 2" active="true"/>
    <joint name="patellofemoral_l_translation3_locked" active="true" joint1="patellofemoral_l_translation3" polycoef="-0.00275 0 0 0 0" solimp="0.9999 0.9999 0.001 0.5 2"/>
  </equality>
  <contact>
    <!-- Leave this comment here to make 'contact' element pretty printed !-->
    <pair geom1="ground-plane" geom2="pelvis_geom_1"/>
    <pair geom1="ground-plane" geom2="pelvis_geom_2"/>
    <pair geom1="ground-plane" geom2="pelvis_geom_3"/>
    <pair geom1="ground-plane" geom2="femur_r_geom_1"/>
    <pair geom1="ground-plane" geom2="tibia_r_geom_1"/>
    <pair geom1="ground-plane" geom2="tibia_r_geom_2"/>
    <pair geom1="ground-plane" geom2="talus_r_geom_1"/>
    <pair geom1="ground-plane" geom2="calcn_r_geom_1"/>
    <pair geom1="ground-plane" geom2="toes_r_geom_1"/>
    <pair geom1="ground-plane" geom2="patella_r_geom_1"/>
    <pair geom1="ground-plane" geom2="femur_l_geom_1"/>
    <pair geom1="ground-plane" geom2="tibia_l_geom_1"/>
    <pair geom1="ground-plane" geom2="tibia_l_geom_2"/>
    <pair geom1="ground-plane" geom2="pylon_l_geom_1"/>
    <pair geom1="ground-plane" geom2="patella_l_geom_1"/>
    <pair geom1="ground-plane" geom2="torso_geom_1"/>
    <pair geom1="ground-plane" geom2="torso_geom_2"/>
    <pair geom1="ground-plane" geom2="torso_geom_3"/>
    <pair geom1="ground-plane" geom2="torso_geom_4"/>
  </contact>
  <keyframe>
    <key name="default-pose" qpos="0 0.93 0 0 0 0 0 0 0 9.537e-08 7.693e-11 0 -1.473e-08 1.089e-08 0 0 0 0.05242 -0.01083 0.00275 0.01051 0 -0 -0 9.537e-08 -7.693e-11 0 -1.473e-08 -1.089e-08 0 0 0 0 -0 0.1745 0.05242 -0.01083 -0.00275 0.01051 0 0 0"/>
  </keyframe>
</mujoco>
